Workbook

Sheet AcCountDeer(Initial)
A1: Greographic | D1: Model Assumptions | G1: Harvest Assumptions | J1: Preharvest Populations | O1: Natural Mortality | T1: Harvest | X1: Model Outcomes
A2: County | B2: Baldwin | D2: N_Preharvest | E2: 65000 | G2: antlered_harvest | H2: 4495 | K2: total | L2: male | M2: female | P2: finite_rate | Q2: instantaeous_rate | R2: 6mo_prob | U2: N_harvest | V2: Percent_harv | Y2: N_Preharvest | Z2: Lambda
A3: Year | B3: 2025 | G3: antlerless_harvest | H3: 6968 | I3: =SUM(H2:H3) -> 11463 | J3: N_preharvest_ad | K3: =ROUND(($E$2*E9),0) -> 33150 | L3: =ROUND(K3*($E$7),0) -> 14255 | M3: =ROUND((K3*$E$6),0) -> 18896 | O3: admale_nhm | P3: 0.2 | Q3: =LN(1-P3) -> -0.22314355 | R3: =1-EXP(Q3*0.5) -> 0.10557281 | T3: admale_harv | U3: =H2-(U5+U7) -> 3840.528 | V3: =ROUND((U3/L3),2) -> 0.27 | X3: 2026 | Y3: =AB20 -> 66668 | Z3: NA
D4: Doe:Buck Ratio | J4: N_preharvest_y1 | K4: =ROUND(($E$2*E10),0) -> 2600 | L4: =ROUND(K4*($E$7),0) -> 1118 | M4: =ROUND((K4*$E$6),0) -> 1482 | O4: adfemale_nhm | P4: 0.229 | Q4: =LN(1-P4) -> -0.26006691 | R4: =1-EXP(Q4*0.5) -> 0.12193394 | T4: adfemale_harv | U4: =H3-(SUM(U6,U8:U10)) -> 4682.496 | V4: =ROUND((U4/M3),2) -> 0.25 | X4: 2027 | Y4: =AB21 -> 65806 | Z4: =ROUND((Y4/Y3),2) -> 0.99
A5: County Size | B5: 1589.9 | C5: mile2 | D5: 130 | E5: 100 | G5: YearlingHarvRate_M | H5: 0.11 | J5: N_preharvest_y | K5: =ROUND(($E$2*E11),0) -> 13000 | L5: =ROUND(K5*($E$7),0) -> 5590 | M5: =ROUND((K5*$E$6),0) -> 7410 | O5: yearmale_nhm | P5: 0.2 | Q5: =LN(1-P5) -> -0.22314355 | R5: =1-EXP(Q5*0.5) -> 0.10557281 | T5: y1male_harv | U5: =(H2-U7)*0.04 -> 160.022 | V5: =ROUND((U5/L4),2) -> 0.14 | X5: 2028 | Y5: =AB22 -> 66335 | Z5: =ROUND((Y5/Y4),2) -> 1.01
A6: Pop Density | B6: =AB20/B5 -> 41.932197 | D6: Demical_Doe | E6: =ROUND(ROUND((D5*100)/(D5+100),2)/100,2) -> 0.57 | G6: YearlingHarvRate_F | H6: 0.18 | J6: N_preharvest_F | K6: =ROUND(($E$2*E12),0) -> 16250 | L6: =ROUND(K6*($E$7),0) -> 6988 | M6: =ROUND((K6*$E$6),0) -> 9263 | O6: yearfemale_nhm | P6: 0.12 | Q6: =LN(1-P6) -> -0.12783337 | R6: =1-EXP(Q6*0.5) -> 0.061916848 | T6: y1female_harv | U6: =(H3-(SUM(U8:U10)))*E10 -> 195.104 | V6: =ROUND((U6/M4),2) -> 0.13 | X6: 2029 | Y6: =AB23 -> 66632 | Z6: =ROUND((Y6/Y5),2) -> 1
D7: Decimal_Buck | E7: =1 -E6 -> 0.43 | G7: FawnHarvRate | H7: 0.12 | O7: fawnmale_nhm | P7: 0.45 | Q7: =LN(1-P7) -> -0.597837 | R7: =1-EXP(Q7*0.5) -> 0.25838015 | T7: yearmale_harv | U7: =H2*H5 -> 494.45 | V7: =ROUND((U7/L5),2) -> 0.09 | X7: 2030 | Y7: =AB24 -> 66650 | Z7: =ROUND((Y7/Y6),2) -> 1
A8: Type | B8: Baseline | O8: fawnfemale_nhm | P8: 0.47 | Q8: =LN(1-P8) -> -0.63487827 | R8: =1-EXP(Q8*0.5) -> 0.27198901 | T8: yearfemale_harv | U8: =H3*H6 -> 1254.24 | V8: =ROUND((U8/M5),2) -> 0.17 | X8: 2031 | Y8: =AB25 -> 66560 | Z8: =ROUND((Y8/Y7),2) -> 1
D9: Adult prop | E9: 0.51 | O9: 6mofawns_nhm | P9: 0.3 | Q9: =LN(1-P9) -> -0.35667494 | R9: =1-EXP(Q9*0.5) -> 0.16333997 | T9: fawnmale_harv | U9: =H3*(H7/2) -> 418.08 | V9: =ROUND((U9/L6),2) -> 0.06 | X9: 2032 | Y9: =AB26 -> 66389 | Z9: =ROUND((Y9/Y8),2) -> 1
D10: Y1 prop | E10: 0.04 | T10: fawnfemale_harv | U10: =H3*(H7/2) -> 418.08 | V10: =ROUND((U10/M6),2) -> 0.05 | X10: 2033 | Y10: =AB27 -> 66176 | Z10: =ROUND((Y10/Y9),2) -> 1
D11: Yearling prop | E11: 0.2 | X11: 2034 | Y11: =AB28 -> 65942 | Z11: =ROUND((Y11/Y10),2) -> 1
D12: Fawn Prop | E12: 0.25 | F12: =SUM(E9:E12) -> 1 | X12: 2035 | Y12: =AB29 -> 65691 | Z12: =ROUND((Y12/Y11),2) -> 1
D14: adfemale_preg | E14: 1.6
D15: yfemale_preg | E15: 0.2
B18: Postharvest (January) | K18: Mid-Year (June) | T18: Preharvest (December) | AD18: N_Non-harvest Mortality | AN18: Additional Mortality
A19: Year | B19: N_admale_posth | C19: N_adfemale_posth | D19: N_y1male_posth | E19: N_y1female_posth | F19: N_ymale_posth | G19: N_yfemale_posth | H19: Nfawnmale_posth | I19: N_fawnfemale_posth | J19: N_postharvest | K19: N_admale_mid | L19: N_adfemale_mid | M19: N_y1male_mid | N19: N_y1female_mid | O19: N_ymale_mid | P19: N_yfemale_mid | Q19: birth_malefawn | R19: birth_femalefawn | S19: N_midseason | T19: N_admale_preh | U19: N_adfemale_preh | V19: N_y1male_preh | W19: N_y1female_preh | X19: N_ymale_preh | Y19: N_yfemale_preh | Z19: N_fawnmale_preh | AA19: N_fawnfemale_preh | AB19: N_preharvest | AD19: N_admale_preh | AE19: N_adfemale_preh | AF19: N_y1male_preh | AG19: N_y1female_preh | AH19: N_ymale_preh | AI19: N_yfemale_preh | AJ19: N_fawnmale_preh | AK19: N_fawnfemale_preh | AL19: Total_nhm | AN19: N_admale_addm | AO19: N_adfemale_addm | AP19: N_y1male_addm | AQ19: N_y1female_addm | AR19: N_ymale_addm | AS19: N_yfemale_addm | AT19: Nfawnmale_addm | AU19: N_fawnfemale_addm | AV19: N_addm
A20: 2026 | B20: =ROUND((L3-(L3*V3)),0) -> 10406 | C20: =ROUND((M3-(M3*V4)),0) -> 14172 | D20: =ROUND((L4 - (L4*$V$5)),0) -> 961 | E20: =ROUND((M4 - (M4*$V$6)),0) -> 1289 | F20: =ROUND((L5-(L5*V7)),0) -> 5087 | G20: =ROUND((M5-(M5*V8)),0) -> 6150 | H20: =ROUND((L6 - (L6*V9)),0) -> 6569 | I20: =ROUND((M6 - (M6*$V$10)),0) -> 8800 | J20: =SUM(B20:I20) -> 53434 | K20: =ROUND((B20+D20) - ((B20+D20)*$R$3),0) -> 10167 | L20: =ROUND((C20+E20) - ((C20+E20)*$R$4),0) -> 13576 | M20: =ROUND((F20-(F20*$R$3)),0) -> 4550 | N20: =ROUND((G20-(G20*$R$4)),0) -> 5400 | O20: =ROUND((H20-(H20*$R$7)),0) -> 4872 | P20: =ROUND((I20-(I20*$R$8)),0) -> 6406 | Q20: =ROUND((((L20*$E$14)+(P20*$E$15)+(N20*$E$14))/2),0) -> 15821 | R20: =Q20 -> 15821 | S20: =SUM(K20:R20) -> 76613 | T20: =ROUND(((K20) - ((K20)*$R$3)),0)-AN20 -> 9094 | U20: =ROUND(((L20) - ((L20)*$R$4)),0)-AO20 -> 11921 | V20: =ROUND((M20 -(M20*$R$3)),0)-AP20 -> 4070 | W20: =ROUND((N20 - (N20*$R$4)),0)-AQ20 -> 4742 | X20: =ROUND((O20 - (O20*$R$5)),0)-AR20 -> 4358 | Y20: =ROUND(((P20) - ((P20)*$R$6)),0)-AS20 -> 6009 | Z20: =ROUND((Q20 - (Q20*$R$9)),0)-AT20 -> 13237 | AA20: =ROUND(((R20) - ((R20)*$R$9)),0)-AU20 -> 13237 | AB20: =SUM(T20:AA20) -> 66668 | AD20: =ROUND(((T20+V20)*$R$3)+((K20)*$R$3), 0) -> 2463 | AE20: =ROUND(((U20+W20)*$R$4)+(L20*R4),0) -> 3687 | AF20: =ROUND(((V20)*$R$3)+(M20*$R$3),0) -> 910 | AG20: =ROUND(((W20)*$R$4)+(N20*$R$4),0) -> 1237 | AH20: =ROUND(((X20)*$R$5)+(O20*$R$5),0) -> 974 | AI20: =ROUND(((Y20)*$R$6)+(P20*$R$6),0) -> 769 | AJ20: =ROUND(((Z20)*$R$7)+(Q20*$R$7),0) -> 7508 | AK20: =ROUND(((AA20)*$R$8)+(R20*$R$8),0) -> 7903 | AL20: =SUM(AD20:AK20) -> 25451 | AN20: 0 | AO20: 0 | AP20: 0 | AQ20: 0 | AR20: 0 | AS20: 0 | AT20: 0 | AU20: 0 | AV20: =SUM(AN20:AU20) -> 0
A21: 2027 | B21: =ROUND((T20-(T20*$V$3)),0) -> 6639 | C21: =ROUND((U20-(U20*$V$4)),0) -> 8941 | D21: =ROUND((V20 - (V20*$V$5)),0) -> 3500 | E21: =ROUND((W20 - (W20*$V$6)),0) -> 4126 | F21: =ROUND((X20-(X20*$V$8)),0) -> 3617 | G21: =ROUND((Y20-(Y20*$V$9)),0) -> 5648 | H21: =ROUND((Z20 - (Z20*$V$9)),0) -> 12443 | I21: =ROUND((AA20 - (AA20*$V$10)),0) -> 12575 | J21: =SUM(B21:I21) -> 57489 | K21: =ROUND((B21+D21) - ((B21+D21)*$R$3),0) -> 9069 | L21: =ROUND((C21+E21) - ((C21+E21)*$R$4),0) -> 11474 | M21: =ROUND((F21-(F21*$R$3)),0) -> 3235 | N21: =ROUND((G21-(G21*$R$4)),0) -> 4959 | O21: =ROUND((H21-(H21*$R$7)),0) -> 9228 | P21: =ROUND((I21-(I21*$R$8)),0) -> 9155 | Q21: =ROUND((((L21*$E$14)+(P21*$E$15)+(N21*$E$14))/2),0) -> 14062 | R21: =Q21 -> 14062 | S21: =SUM(K21:R21) -> 75244 | T21: =ROUND(((K21) - ((K21)*$R$3)),0)-AN21 -> 8112 | U21: =ROUND(((L21) - ((L21)*$R$4)),0)-AO21 -> 10075 | V21: =ROUND((M21 -(M21*$R$3)),0)-AP21 -> 2893 | W21: =ROUND((N21 - (N21*$R$4)),0)-AQ21 -> 4354 | X21: =ROUND((O21 - (O21*$R$5)),0)-AR21 -> 8254 | Y21: =ROUND(((P21) - ((P21)*$R$6)),0)-AS21 -> 8588 | Z21: =ROUND((Q21 - (Q21*$R$9)),0)-AT21 -> 11765 | AA21: =ROUND(((R21) - ((R21)*$R$9)),0)-AU21 -> 11765 | AB21: =SUM(T21:AA21) -> 65806 | AD21: =ROUND(((T21+V21)*$R$3)+((K21)*$R$3), 0) -> 2119 | AE21: =ROUND(((U21+W21)*$R$4)+(L21*R5),0) -> 2971 | AF21: =ROUND(((V21)*$R$3)+(M21*$R$3),0) -> 647 | AG21: =ROUND(((W21)*$R$4)+(N21*$R$4),0) -> 1136 | AH21: =ROUND(((X21)*$R$5)+(O21*$R$5),0) -> 1846 | AI21: =ROUND(((Y21)*$R$6)+(P21*$R$6),0) -> 1099 | AJ21: =ROUND(((Z21)*$R$7)+(Q21*$R$7),0) -> 6673 | AK21: =ROUND(((AA21)*$R$8)+(R21*$R$8),0) -> 7025 | AL21: =SUM(AD21:AK21) -> 23516 | AN21: 0 | AO21: 0 | AP21: 0 | AQ21: 0 | AR21: 0 | AS21: 0 | AT21: 0 | AU21: 0 | AV21: =SUM(AN21:AU21) -> 0
A22: 2028 | B22: =ROUND((T21-(T21*$V$3)),0) -> 5922 | C22: =ROUND((U21-(U21*$V$4)),0) -> 7556 | D22: =ROUND((V21 - (V21*$V$5)),0) -> 2488 | E22: =ROUND((W21 - (W21*$V$6)),0) -> 3788 | F22: =ROUND((X21-(X21*$V$8)),0) -> 6851 | G22: =ROUND((Y21-(Y21*$V$9)),0) -> 8073 | H22: =ROUND((Z21 - (Z21*$V$9)),0) -> 11059 | I22: =ROUND((AA21 - (AA21*$V$10)),0) -> 11177 | J22: =SUM(B22:I22) -> 56914 | K22: =ROUND((B22+D22) - ((B22+D22)*$R$3),0) -> 7522 | L22: =ROUND((C22+E22) - ((C22+E22)*$R$4),0) -> 9961 | M22: =ROUND((F22-(F22*$R$3)),0) -> 6128 | N22: =ROUND((G22-(G22*$R$4)),0) -> 7089 | O22: =ROUND((H22-(H22*$R$7)),0) -> 8202 | P22: =ROUND((I22-(I22*$R$8)),0) -> 8137 | Q22: =ROUND((((L22*$E$14)+(P22*$E$15)+(N22*$E$14))/2),0) -> 14454 | R22: =Q22 -> 14454 | S22: =SUM(K22:R22) -> 75947 | T22: =ROUND(((K22) - ((K22)*$R$3)),0)-AN22 -> 6728 | U22: =ROUND(((L22) - ((L22)*$R$4)),0)-AO22 -> 8746 | V22: =ROUND((M22 -(M22*$R$3)),0)-AP22 -> 5481 | W22: =ROUND((N22 - (N22*$R$4)),0)-AQ22 -> 6225 | X22: =ROUND((O22 - (O22*$R$5)),0)-AR22 -> 7336 | Y22: =ROUND(((P22) - ((P22)*$R$6)),0)-AS22 -> 7633 | Z22: =ROUND((Q22 - (Q22*$R$9)),0)-AT22 -> 12093 | AA22: =ROUND(((R22) - ((R22)*$R$9)),0)-AU22 -> 12093 | AB22: =SUM(T22:AA22) -> 66335 | AD22: =ROUND(((T22+V22)*$R$3)+((K22)*$R$3), 0) -> 2083 | AE22: =ROUND(((U22+W22)*$R$4)+(L22*R6),0) -> 2442 | AF22: =ROUND(((V22)*$R$3)+(M22*$R$3),0) -> 1226 | AG22: =ROUND(((W22)*$R$4)+(N22*$R$4),0) -> 1623 | AH22: =ROUND(((X22)*$R$5)+(O22*$R$5),0) -> 1640 | AI22: =ROUND(((Y22)*$R$6)+(P22*$R$6),0) -> 976 | AJ22: =ROUND(((Z22)*$R$7)+(Q22*$R$7),0) -> 6859 | AK22: =ROUND(((AA22)*$R$8)+(R22*$R$8),0) -> 7220 | AL22: =SUM(AD22:AK22) -> 24069 | AN22: 0 | AO22: 0 | AP22: 0 | AQ22: 0 | AR22: 0 | AS22: 0 | AT22: 0 | AU22: 0 | AV22: =SUM(AN22:AU22) -> 0
A23: 2029 | B23: =ROUND((T22-(T22*$V$3)),0) -> 4911 | C23: =ROUND((U22-(U22*$V$4)),0) -> 6560 | D23: =ROUND((V22 - (V22*$V$5)),0) -> 4714 | E23: =ROUND((W22 - (W22*$V$6)),0) -> 5416 | F23: =ROUND((X22-(X22*$V$8)),0) -> 6089 | G23: =ROUND((Y22-(Y22*$V$9)),0) -> 7175 | H23: =ROUND((Z22 - (Z22*$V$9)),0) -> 11367 | I23: =ROUND((AA22 - (AA22*$V$10)),0) -> 11488 | J23: =SUM(B23:I23) -> 57720 | K23: =ROUND((B23+D23) - ((B23+D23)*$R$3),0) -> 8609 | L23: =ROUND((C23+E23) - ((C23+E23)*$R$4),0) -> 10516 | M23: =ROUND((F23-(F23*$R$3)),0) -> 5446 | N23: =ROUND((G23-(G23*$R$4)),0) -> 6300 | O23: =ROUND((H23-(H23*$R$7)),0) -> 8430 | P23: =ROUND((I23-(I23*$R$8)),0) -> 8363 | Q23: =ROUND((((L23*$E$14)+(P23*$E$15)+(N23*$E$14))/2),0) -> 14289 | R23: =Q23 -> 14289 | S23: =SUM(K23:R23) -> 76242 | T23: =ROUND(((K23) - ((K23)*$R$3)),0)-AN23 -> 7700 | U23: =ROUND(((L23) - ((L23)*$R$4)),0)-AO23 -> 9234 | V23: =ROUND((M23 -(M23*$R$3)),0)-AP23 -> 4871 | W23: =ROUND((N23 - (N23*$R$4)),0)-AQ23 -> 5532 | X23: =ROUND((O23 - (O23*$R$5)),0)-AR23 -> 7540 | Y23: =ROUND(((P23) - ((P23)*$R$6)),0)-AS23 -> 7845 | Z23: =ROUND((Q23 - (Q23*$R$9)),0)-AT23 -> 11955 | AA23: =ROUND(((R23) - ((R23)*$R$9)),0)-AU23 -> 11955 | AB23: =SUM(T23:AA23) -> 66632 | AD23: =ROUND(((T23+V23)*$R$3)+((K23)*$R$3), 0) -> 2236 | AE23: =ROUND(((U23+W23)*$R$4)+(L23*R7),0) -> 4518 | AF23: =ROUND(((V23)*$R$3)+(M23*$R$3),0) -> 1089 | AG23: =ROUND(((W23)*$R$4)+(N23*$R$4),0) -> 1443 | AH23: =ROUND(((X23)*$R$5)+(O23*$R$5),0) -> 1686 | AI23: =ROUND(((Y23)*$R$6)+(P23*$R$6),0) -> 1004 | AJ23: =ROUND(((Z23)*$R$7)+(Q23*$R$7),0) -> 6781 | AK23: =ROUND(((AA23)*$R$8)+(R23*$R$8),0) -> 7138 | AL23: =SUM(AD23:AK23) -> 25895 | AN23: 0 | AO23: 0 | AP23: 0 | AQ23: 0 | AR23: 0 | AS23: 0 | AT23: 0 | AU23: 0 | AV23: =SUM(AN23:AU23) -> 0
A24: 2030 | B24: =ROUND((T23-(T23*$V$3)),0) -> 5621 | C24: =ROUND((U23-(U23*$V$4)),0) -> 6926 | D24: =ROUND((V23 - (V23*$V$5)),0) -> 4189 | E24: =ROUND((W23 - (W23*$V$6)),0) -> 4813 | F24: =ROUND((X23-(X23*$V$8)),0) -> 6258 | G24: =ROUND((Y23-(Y23*$V$9)),0) -> 7374 | H24: =ROUND((Z23 - (Z23*$V$9)),0) -> 11238 | I24: =ROUND((AA23 - (AA23*$V$10)),0) -> 11357 | J24: =SUM(B24:I24) -> 57776 | K24: =ROUND((B24+D24) - ((B24+D24)*$R$3),0) -> 8774 | L24: =ROUND((C24+E24) - ((C24+E24)*$R$4),0) -> 10308 | M24: =ROUND((F24-(F24*$R$3)),0) -> 5597 | N24: =ROUND((G24-(G24*$R$4)),0) -> 6475 | O24: =ROUND((H24-(H24*$R$7)),0) -> 8334 | P24: =ROUND((I24-(I24*$R$8)),0) -> 8268 | Q24: =ROUND((((L24*$E$14)+(P24*$E$15)+(N24*$E$14))/2),0) -> 14253 | R24: =Q24 -> 14253 | S24: =SUM(K24:R24) -> 76262 | T24: =ROUND(((K24) - ((K24)*$R$3)),0)-AN24 -> 7848 | U24: =ROUND(((L24) - ((L24)*$R$4)),0)-AO24 -> 9051 | V24: =ROUND((M24 -(M24*$R$3)),0)-AP24 -> 5006 | W24: =ROUND((N24 - (N24*$R$4)),0)-AQ24 -> 5685 | X24: =ROUND((O24 - (O24*$R$5)),0)-AR24 -> 7454 | Y24: =ROUND(((P24) - ((P24)*$R$6)),0)-AS24 -> 7756 | Z24: =ROUND((Q24 - (Q24*$R$9)),0)-AT24 -> 11925 | AA24: =ROUND(((R24) - ((R24)*$R$9)),0)-AU24 -> 11925 | AB24: =SUM(T24:AA24) -> 66650 | AD24: =ROUND(((T24+V24)*$R$3)+((K24)*$R$3), 0) -> 2283 | AE24: =ROUND(((U24+W24)*$R$4)+(L24*R8),0) -> 4600 | AF24: =ROUND(((V24)*$R$3)+(M24*$R$3),0) -> 1119 | AG24: =ROUND(((W24)*$R$4)+(N24*$R$4),0) -> 1483 | AH24: =ROUND(((X24)*$R$5)+(O24*$R$5),0) -> 1667 | AI24: =ROUND(((Y24)*$R$6)+(P24*$R$6),0) -> 992 | AJ24: =ROUND(((Z24)*$R$7)+(Q24*$R$7),0) -> 6764 | AK24: =ROUND(((AA24)*$R$8)+(R24*$R$8),0) -> 7120 | AL24: =SUM(AD24:AK24) -> 26028 | AN24: 0 | AO24: 0 | AP24: 0 | AQ24: 0 | AR24: 0 | AS24: 0 | AT24: 0 | AU24: 0 | AV24: =SUM(AN24:AU24) -> 0
A25: 2031 | B25: =ROUND((T24-(T24*$V$3)),0) -> 5729 | C25: =ROUND((U24-(U24*$V$4)),0) -> 6788 | D25: =ROUND((V24 - (V24*$V$5)),0) -> 4305 | E25: =ROUND((W24 - (W24*$V$6)),0) -> 4946 | F25: =ROUND((X24-(X24*$V$8)),0) -> 6187 | G25: =ROUND((Y24-(Y24*$V$9)),0) -> 7291 | H25: =ROUND((Z24 - (Z24*$V$9)),0) -> 11210 | I25: =ROUND((AA24 - (AA24*$V$10)),0) -> 11329 | J25: =SUM(B25:I25) -> 57785 | K25: =ROUND((B25+D25) - ((B25+D25)*$R$3),0) -> 8975 | L25: =ROUND((C25+E25) - ((C25+E25)*$R$4),0) -> 10303 | M25: =ROUND((F25-(F25*$R$3)),0) -> 5534 | N25: =ROUND((G25-(G25*$R$4)),0) -> 6402 | O25: =ROUND((H25-(H25*$R$7)),0) -> 8314 | P25: =ROUND((I25-(I25*$R$8)),0) -> 8248 | Q25: =ROUND((((L25*$E$14)+(P25*$E$15)+(N25*$E$14))/2),0) -> 14189 | R25: =Q25 -> 14189 | S25: =SUM(K25:R25) -> 76154 | T25: =ROUND(((K25) - ((K25)*$R$3)),0)-AN25 -> 8027 | U25: =ROUND(((L25) - ((L25)*$R$4)),0)-AO25 -> 9047 | V25: =ROUND((M25 -(M25*$R$3)),0)-AP25 -> 4950 | W25: =ROUND((N25 - (N25*$R$4)),0)-AQ25 -> 5621 | X25: =ROUND((O25 - (O25*$R$5)),0)-AR25 -> 7436 | Y25: =ROUND(((P25) - ((P25)*$R$6)),0)-AS25 -> 7737 | Z25: =ROUND((Q25 - (Q25*$R$9)),0)-AT25 -> 11871 | AA25: =ROUND(((R25) - ((R25)*$R$9)),0)-AU25 -> 11871 | AB25: =SUM(T25:AA25) -> 66560 | AD25: =ROUND(((T25+V25)*$R$3)+((K25)*$R$3), 0) -> 2318 | AE25: =ROUND(((U25+W25)*$R$4)+(L25*R9),0) -> 3471 | AF25: =ROUND(((V25)*$R$3)+(M25*$R$3),0) -> 1107 | AG25: =ROUND(((W25)*$R$4)+(N25*$R$4),0) -> 1466 | AH25: =ROUND(((X25)*$R$5)+(O25*$R$5),0) -> 1663 | AI25: =ROUND(((Y25)*$R$6)+(P25*$R$6),0) -> 990 | AJ25: =ROUND(((Z25)*$R$7)+(Q25*$R$7),0) -> 6733 | AK25: =ROUND(((AA25)*$R$8)+(R25*$R$8),0) -> 7088 | AL25: =SUM(AD25:AK25) -> 24836 | AN25: 0 | AO25: 0 | AP25: 0 | AQ25: 0 | AR25: 0 | AS25: 0 | AT25: 0 | AU25: 0 | AV25: =SUM(AN25:AU25) -> 0
A26: 2032 | B26: =ROUND((T25-(T25*$V$3)),0) -> 5860 | C26: =ROUND((U25-(U25*$V$4)),0) -> 6785 | D26: =ROUND((V25 - (V25*$V$5)),0) -> 4257 | E26: =ROUND((W25 - (W25*$V$6)),0) -> 4890 | F26: =ROUND((X25-(X25*$V$8)),0) -> 6172 | G26: =ROUND((Y25-(Y25*$V$9)),0) -> 7273 | H26: =ROUND((Z25 - (Z25*$V$9)),0) -> 11159 | I26: =ROUND((AA25 - (AA25*$V$10)),0) -> 11277 | J26: =SUM(B26:I26) -> 57673 | K26: =ROUND((B26+D26) - ((B26+D26)*$R$3),0) -> 9049 | L26: =ROUND((C26+E26) - ((C26+E26)*$R$4),0) -> 10251 | M26: =ROUND((F26-(F26*$R$3)),0) -> 5520 | N26: =ROUND((G26-(G26*$R$4)),0) -> 6386 | O26: =ROUND((H26-(H26*$R$7)),0) -> 8276 | P26: =ROUND((I26-(I26*$R$8)),0) -> 8210 | Q26: =ROUND((((L26*$E$14)+(P26*$E$15)+(N26*$E$14))/2),0) -> 14131 | R26: =Q26 -> 14131 | S26: =SUM(K26:R26) -> 75954 | T26: =ROUND(((K26) - ((K26)*$R$3)),0)-AN26 -> 8094 | U26: =ROUND(((L26) - ((L26)*$R$4)),0)-AO26 -> 9001 | V26: =ROUND((M26 -(M26*$R$3)),0)-AP26 -> 4937 | W26: =ROUND((N26 - (N26*$R$4)),0)-AQ26 -> 5607 | X26: =ROUND((O26 - (O26*$R$5)),0)-AR26 -> 7402 | Y26: =ROUND(((P26) - ((P26)*$R$6)),0)-AS26 -> 7702 | Z26: =ROUND((Q26 - (Q26*$R$9)),0)-AT26 -> 11823 | AA26: =ROUND(((R26) - ((R26)*$R$9)),0)-AU26 -> 11823 | AB26: =SUM(T26:AA26) -> 66389 | AD26: =ROUND(((T26+V26)*$R$3)+((K26)*$R$3), 0) -> 2331 | AE26: =ROUND(((U26+W26)*$R$4)+(L26*R10),0) -> 1781 | AF26: =ROUND(((V26)*$R$3)+(M26*$R$3),0) -> 1104 | AG26: =ROUND(((W26)*$R$4)+(N26*$R$4),0) -> 1462 | AH26: =ROUND(((X26)*$R$5)+(O26*$R$5),0) -> 1655 | AI26: =ROUND(((Y26)*$R$6)+(P26*$R$6),0) -> 985 | AJ26: =ROUND(((Z26)*$R$7)+(Q26*$R$7),0) -> 6706 | AK26: =ROUND(((AA26)*$R$8)+(R26*$R$8),0) -> 7059 | AL26: =SUM(AD26:AK26) -> 23083 | AN26: 0 | AO26: 0 | AP26: 0 | AQ26: 0 | AR26: 0 | AS26: 0 | AT26: 0 | AU26: 0 | AV26: =SUM(AN26:AU26) -> 0
A27: 2033 | B27: =ROUND((T26-(T26*$V$3)),0) -> 5909 | C27: =ROUND((U26-(U26*$V$4)),0) -> 6751 | D27: =ROUND((V26 - (V26*$V$5)),0) -> 4246 | E27: =ROUND((W26 - (W26*$V$6)),0) -> 4878 | F27: =ROUND((X26-(X26*$V$8)),0) -> 6144 | G27: =ROUND((Y26-(Y26*$V$9)),0) -> 7240 | H27: =ROUND((Z26 - (Z26*$V$9)),0) -> 11114 | I27: =ROUND((AA26 - (AA26*$V$10)),0) -> 11232 | J27: =SUM(B27:I27) -> 57514 | K27: =ROUND((B27+D27) - ((B27+D27)*$R$3),0) -> 9083 | L27: =ROUND((C27+E27) - ((C27+E27)*$R$4),0) -> 10211 | M27: =ROUND((F27-(F27*$R$3)),0) -> 5495 | N27: =ROUND((G27-(G27*$R$4)),0) -> 6357 | O27: =ROUND((H27-(H27*$R$7)),0) -> 8242 | P27: =ROUND((I27-(I27*$R$8)),0) -> 8177 | Q27: =ROUND((((L27*$E$14)+(P27*$E$15)+(N27*$E$14))/2),0) -> 14072 | R27: =Q27 -> 14072 | S27: =SUM(K27:R27) -> 75709 | T27: =ROUND(((K27) - ((K27)*$R$3)),0)-AN27 -> 8124 | U27: =ROUND(((L27) - ((L27)*$R$4)),0)-AO27 -> 8966 | V27: =ROUND((M27 -(M27*$R$3)),0)-AP27 -> 4915 | W27: =ROUND((N27 - (N27*$R$4)),0)-AQ27 -> 5582 | X27: =ROUND((O27 - (O27*$R$5)),0)-AR27 -> 7372 | Y27: =ROUND(((P27) - ((P27)*$R$6)),0)-AS27 -> 7671 | Z27: =ROUND((Q27 - (Q27*$R$9)),0)-AT27 -> 11773 | AA27: =ROUND(((R27) - ((R27)*$R$9)),0)-AU27 -> 11773 | AB27: =SUM(T27:AA27) -> 66176 | AD27: =ROUND(((T27+V27)*$R$3)+((K27)*$R$3), 0) -> 2335 | AE27: =ROUND(((U27+W27)*$R$4)+(L27*R11),0) -> 1774 | AF27: =ROUND(((V27)*$R$3)+(M27*$R$3),0) -> 1099 | AG27: =ROUND(((W27)*$R$4)+(N27*$R$4),0) -> 1456 | AH27: =ROUND(((X27)*$R$5)+(O27*$R$5),0) -> 1648 | AI27: =ROUND(((Y27)*$R$6)+(P27*$R$6),0) -> 981 | AJ27: =ROUND(((Z27)*$R$7)+(Q27*$R$7),0) -> 6678 | AK27: =ROUND(((AA27)*$R$8)+(R27*$R$8),0) -> 7030 | AL27: =SUM(AD27:AK27) -> 23001 | AN27: 0 | AO27: 0 | AP27: 0 | AQ27: 0 | AR27: 0 | AS27: 0 | AT27: 0 | AU27: 0 | AV27: =SUM(AN27:AU27) -> 0
A28: 2034 | B28: =ROUND((T27-(T27*$V$3)),0) -> 5931 | C28: =ROUND((U27-(U27*$V$4)),0) -> 6725 | D28: =ROUND((V27 - (V27*$V$5)),0) -> 4227 | E28: =ROUND((W27 - (W27*$V$6)),0) -> 4856 | F28: =ROUND((X27-(X27*$V$8)),0) -> 6119 | G28: =ROUND((Y27-(Y27*$V$9)),0) -> 7211 | H28: =ROUND((Z27 - (Z27*$V$9)),0) -> 11067 | I28: =ROUND((AA27 - (AA27*$V$10)),0) -> 11184 | J28: =SUM(B28:I28) -> 57320 | K28: =ROUND((B28+D28) - ((B28+D28)*$R$3),0) -> 9086 | L28: =ROUND((C28+E28) - ((C28+E28)*$R$4),0) -> 10169 | M28: =ROUND((F28-(F28*$R$3)),0) -> 5473 | N28: =ROUND((G28-(G28*$R$4)),0) -> 6332 | O28: =ROUND((H28-(H28*$R$7)),0) -> 8208 | P28: =ROUND((I28-(I28*$R$8)),0) -> 8142 | Q28: =ROUND((((L28*$E$14)+(P28*$E$15)+(N28*$E$14))/2),0) -> 14015 | R28: =Q28 -> 14015 | S28: =SUM(K28:R28) -> 75440 | T28: =ROUND(((K28) - ((K28)*$R$3)),0)-AN28 -> 8127 | U28: =ROUND(((L28) - ((L28)*$R$4)),0)-AO28 -> 8929 | V28: =ROUND((M28 -(M28*$R$3)),0)-AP28 -> 4895 | W28: =ROUND((N28 - (N28*$R$4)),0)-AQ28 -> 5560 | X28: =ROUND((O28 - (O28*$R$5)),0)-AR28 -> 7341 | Y28: =ROUND(((P28) - ((P28)*$R$6)),0)-AS28 -> 7638 | Z28: =ROUND((Q28 - (Q28*$R$9)),0)-AT28 -> 11726 | AA28: =ROUND(((R28) - ((R28)*$R$9)),0)-AU28 -> 11726 | AB28: =SUM(T28:AA28) -> 65942 | AD28: =ROUND(((T28+V28)*$R$3)+((K28)*$R$3), 0) -> 2334 | AE28: =ROUND(((U28+W28)*$R$4)+(L28*R12),0) -> 1767 | AF28: =ROUND(((V28)*$R$3)+(M28*$R$3),0) -> 1095 | AG28: =ROUND(((W28)*$R$4)+(N28*$R$4),0) -> 1450 | AH28: =ROUND(((X28)*$R$5)+(O28*$R$5),0) -> 1642 | AI28: =ROUND(((Y28)*$R$6)+(P28*$R$6),0) -> 977 | AJ28: =ROUND(((Z28)*$R$7)+(Q28*$R$7),0) -> 6651 | AK28: =ROUND(((AA28)*$R$8)+(R28*$R$8),0) -> 7001 | AL28: =SUM(AD28:AK28) -> 22917 | AN28: 0 | AO28: 0 | AP28: 0 | AQ28: 0 | AR28: 0 | AS28: 0 | AT28: 0 | AU28: 0 | AV28: =SUM(AN28:AU28) -> 0
A29: 2035 | B29: =ROUND((T28-(T28*$V$3)),0) -> 5933 | C29: =ROUND((U28-(U28*$V$4)),0) -> 6697 | D29: =ROUND((V28 - (V28*$V$5)),0) -> 4210 | E29: =ROUND((W28 - (W28*$V$6)),0) -> 4837 | F29: =ROUND((X28-(X28*$V$8)),0) -> 6093 | G29: =ROUND((Y28-(Y28*$V$9)),0) -> 7180 | H29: =ROUND((Z28 - (Z28*$V$9)),0) -> 11022 | I29: =ROUND((AA28 - (AA28*$V$10)),0) -> 11140 | J29: =SUM(B29:I29) -> 57112 | K29: =ROUND((B29+D29) - ((B29+D29)*$R$3),0) -> 9072 | L29: =ROUND((C29+E29) - ((C29+E29)*$R$4),0) -> 10128 | M29: =ROUND((F29-(F29*$R$3)),0) -> 5450 | N29: =ROUND((G29-(G29*$R$4)),0) -> 6305 | O29: =ROUND((H29-(H29*$R$7)),0) -> 8174 | P29: =ROUND((I29-(I29*$R$8)),0) -> 8110 | Q29: =ROUND((((L29*$E$14)+(P29*$E$15)+(N29*$E$14))/2),0) -> 13957 | R29: =Q29 -> 13957 | S29: =SUM(K29:R29) -> 75153 | T29: =ROUND(((K29) - ((K29)*$R$3)),0)-AN29 -> 8114 | U29: =ROUND(((L29) - ((L29)*$R$4)),0)-AO29 -> 8893 | V29: =ROUND((M29 -(M29*$R$3)),0)-AP29 -> 4875 | W29: =ROUND((N29 - (N29*$R$4)),0)-AQ29 -> 5536 | X29: =ROUND((O29 - (O29*$R$5)),0)-AR29 -> 7311 | Y29: =ROUND(((P29) - ((P29)*$R$6)),0)-AS29 -> 7608 | Z29: =ROUND((Q29 - (Q29*$R$9)),0)-AT29 -> 11677 | AA29: =ROUND(((R29) - ((R29)*$R$9)),0)-AU29 -> 11677 | AB29: =SUM(T29:AA29) -> 65691 | AD29: =ROUND(((T29+V29)*$R$3)+((K29)*$R$3), 0) -> 2329 | AE29: =ROUND(((U29+W29)*$R$4)+(L29*R13),0) -> 1759 | AF29: =ROUND(((V29)*$R$3)+(M29*$R$3),0) -> 1090 | AG29: =ROUND(((W29)*$R$4)+(N29*$R$4),0) -> 1444 | AH29: =ROUND(((X29)*$R$5)+(O29*$R$5),0) -> 1635 | AI29: =ROUND(((Y29)*$R$6)+(P29*$R$6),0) -> 973 | AJ29: =ROUND(((Z29)*$R$7)+(Q29*$R$7),0) -> 6623 | AK29: =ROUND(((AA29)*$R$8)+(R29*$R$8),0) -> 6972 | AL29: =SUM(AD29:AK29) -> 22825 | AN29: 0 | AO29: 0 | AP29: 0 | AQ29: 0 | AR29: 0 | AS29: 0 | AT29: 0 | AU29: 0 | AV29: =SUM(AN29:AU29) -> 0
A31: Modeled Harvest Projections | L31: Combined Age Classes
B32: Model_Harvest | C32: Model_harvest_adM | D32: Model_harvest_adF | E32: Model_harvest_y1M | F32: Model_harvest_y1F | G32: Model_harvest_yM | H32: Model_harvest_yF | I32: Model_harvest_fawnM | J32: Model_harvest_fawnF | M32: N_CFawn | N32: N_Cyear | O32: N_CY1 | P32: N_Cadult
A33: 2026 | B33: =SUM(C33:J33) -> 9179 | C33: =T20-B21 -> 2455 | D33: =U20-C21 -> 2980 | E33: =V20-D21 -> 570 | F33: =W20-E21 -> 616 | G33: =X20-F21 -> 741 | H33: =Y20-G21 -> 361 | I33: =Z20-H21 -> 794 | J33: =AA20-I21 -> 662 | L33: 2026 | M33: =AA20+Z20 -> 26474 | N33: =Y20+X20 -> 10367 | O33: =W20+V20 -> 8812 | P33: =U20+T20 -> 21015
A34: 2027 | B34: =SUM(C34:J34) -> 8892 | C34: =T21-B22 -> 2190 | D34: =U21-C22 -> 2519 | E34: =V21-D22 -> 405 | F34: =W21-E22 -> 566 | G34: =X21-F22 -> 1403 | H34: =Y21-G22 -> 515 | I34: =Z21-H22 -> 706 | J34: =AA21-I22 -> 588 | L34: 2027 | M34: =AA21+Z21 -> 23530 | N34: =Y21+X21 -> 16842 | O34: =W21+V21 -> 7247 | P34: =U21+T21 -> 18187
A35: 2028 | B35: =SUM(C35:J35) -> 8615 | C35: =T22-B23 -> 1817 | D35: =U22-C23 -> 2186 | E35: =V22-D23 -> 767 | F35: =W22-E23 -> 809 | G35: =X22-F23 -> 1247 | H35: =Y22-G23 -> 458 | I35: =Z22-H23 -> 726 | J35: =AA22-I23 -> 605 | L35: 2028 | M35: =AA22+Z22 -> 24186 | N35: =Y22+X22 -> 14969 | O35: =W22+V22 -> 11706 | P35: =U22+T22 -> 15474
A36: 2029 | B36: =SUM(C36:J36) -> 8856 | C36: =T23-B24 -> 2079 | D36: =U23-C24 -> 2308 | E36: =V23-D24 -> 682 | F36: =W23-E24 -> 719 | G36: =X23-F24 -> 1282 | H36: =Y23-G24 -> 471 | I36: =Z23-H24 -> 717 | J36: =AA23-I24 -> 598 | L36: 2029 | M36: =AA23+Z23 -> 23910 | N36: =Y23+X23 -> 15385 | O36: =W23+V23 -> 10403 | P36: =U23+T23 -> 16934
A37: 2030 | B37: =SUM(C37:J37) -> 8865 | C37: =T24-B25 -> 2119 | D37: =U24-C25 -> 2263 | E37: =V24-D25 -> 701 | F37: =W24-E25 -> 739 | G37: =X24-F25 -> 1267 | H37: =Y24-G25 -> 465 | I37: =Z24-H25 -> 715 | J37: =AA24-I25 -> 596 | L37: 2030 | M37: =AA24+Z24 -> 23850 | N37: =Y24+X24 -> 15210 | O37: =W24+V24 -> 10691 | P37: =U24+T24 -> 16899
A38: 2031 | B38: =SUM(C38:J38) -> 8887 | C38: =T25-B26 -> 2167 | D38: =U25-C26 -> 2262 | E38: =V25-D26 -> 693 | F38: =W25-E26 -> 731 | G38: =X25-F26 -> 1264 | H38: =Y25-G26 -> 464 | I38: =Z25-H26 -> 712 | J38: =AA25-I26 -> 594 | L38: 2031 | M38: =AA25+Z25 -> 23742 | N38: =Y25+X25 -> 15173 | O38: =W25+V25 -> 10571 | P38: =U25+T25 -> 17074
A39: 2032 | B39: =SUM(C39:J39) -> 8875 | C39: =T26-B27 -> 2185 | D39: =U26-C27 -> 2250 | E39: =V26-D27 -> 691 | F39: =W26-E27 -> 729 | G39: =X26-F27 -> 1258 | H39: =Y26-G27 -> 462 | I39: =Z26-H27 -> 709 | J39: =AA26-I27 -> 591 | L39: 2032 | M39: =AA26+Z26 -> 23646 | N39: =Y26+X26 -> 15104 | O39: =W26+V26 -> 10544 | P39: =U26+T26 -> 17095
A40: 2033 | B40: =SUM(C40:J40) -> 8856 | C40: =T27-B28 -> 2193 | D40: =U27-C28 -> 2241 | E40: =V27-D28 -> 688 | F40: =W27-E28 -> 726 | G40: =X27-F28 -> 1253 | H40: =Y27-G28 -> 460 | I40: =Z27-H28 -> 706 | J40: =AA27-I28 -> 589 | L40: 2033 | M40: =AA27+Z27 -> 23546 | N40: =Y27+X27 -> 15043 | O40: =W27+V27 -> 10497 | P40: =U27+T27 -> 17090
A41: 2034 | B41: =SUM(C41:J41) -> 8830 | C41: =T28-B29 -> 2194 | D41: =U28-C29 -> 2232 | E41: =V28-D29 -> 685 | F41: =W28-E29 -> 723 | G41: =X28-F29 -> 1248 | H41: =Y28-G29 -> 458 | I41: =Z28-H29 -> 704 | J41: =AA28-I29 -> 586 | L41: 2034 | M41: =AA28+Z28 -> 23452 | N41: =Y28+X28 -> 14979 | O41: =W28+V28 -> 10455 | P41: =U28+T28 -> 17056
A42: 2035 | B42: na | C42: na | D42: na | E42: na | F42: na | G42: na | H42: na | I42: na | J42: na | L42: 2035 | M42: =AA29+Z29 -> 23354 | N42: =Y29+X29 -> 14919 | O42: =W29+V29 -> 10411 | P42: =U29+T29 -> 17007
A44: Modeled Harvest Averages
B45: Male | C45: Female
...

Sheet AcCountDeer(Trial1)
A1: Greographic | D1: Model Assumptions | G1: Harvest Assumptions | J1: Preharvest Populations | O1: Natural Mortality | T1: Harvest | X1: Model Outcomes
A2: County | B2: Baldwin | D2: N_Preharvest | E2: 65000 | G2: antlered_harvest | H2: 4495 | K2: total | L2: male | M2: female | P2: finite_rate | Q2: instantaeous_rate | R2: 6mo_prob | U2: N_harvest | V2: Percent_harv | Y2: N_Preharvest | Z2: Lambda
A3: Year | B3: 2025 | G3: antlerless_harvest | H3: 6968 | I3: =SUM(H2:H3) -> 11463 | J3: N_preharvest_ad | K3: =ROUND(($E$2*E9),0) -> 33150 | L3: =ROUND(K3*($E$7),0) -> 14255 | M3: =ROUND((K3*$E$6),0) -> 18896 | O3: admale_nhm | P3: 0.2 | Q3: =LN(1-P3) -> -0.22314355 | R3: =1-EXP(Q3*0.5) -> 0.10557281 | T3: admale_harv | U3: =H2-(U5+U7) -> 3840.528 | V3: =ROUND((U3/L3),2) -> 0.27 | X3: 2026 | Y3: =AB20 -> 60284 | Z3: NA
D4: Doe:Buck Ratio | J4: N_preharvest_y1 | K4: =ROUND(($E$2*E10),0) -> 2600 | L4: =ROUND(K4*($E$7),0) -> 1118 | M4: =ROUND((K4*$E$6),0) -> 1482 | O4: adfemale_nhm | P4: 0.229 | Q4: =LN(1-P4) -> -0.26006691 | R4: =1-EXP(Q4*0.5) -> 0.12193394 | T4: adfemale_harv | U4: =H3-(SUM(U6,U8:U10)) -> 4682.496 | V4: 0.375 | X4: 2027 | Y4: =AB21 -> 55347 | Z4: =ROUND((Y4/Y3),2) -> 0.92
A5: County Size | B5: 1589.9 | C5: mile2 | D5: 130 | E5: 100 | G5: YearlingHarvRate_M | H5: 0.11 | J5: N_preharvest_y | K5: =ROUND(($E$2*E11),0) -> 13000 | L5: =ROUND(K5*($E$7),0) -> 5590 | M5: =ROUND((K5*$E$6),0) -> 7410 | O5: yearmale_nhm | P5: 0.2 | Q5: =LN(1-P5) -> -0.22314355 | R5: =1-EXP(Q5*0.5) -> 0.10557281 | T5: y1male_harv | U5: =(H2-U7)*0.04 -> 160.022 | V5: =ROUND((U5/L4),2) -> 0.14 | X5: 2028 | Y5: =AB22 -> 51884 | Z5: =ROUND((Y5/Y4),2) -> 0.94
A6: Pop Density | B6: =AB20/B5 -> 37.91685 | D6: Demical_Doe | E6: =ROUND(ROUND((D5*100)/(D5+100),2)/100,2) -> 0.57 | G6: YearlingHarvRate_F | H6: 0.18 | J6: N_preharvest_F | K6: =ROUND(($E$2*E12),0) -> 16250 | L6: =ROUND(K6*($E$7),0) -> 6988 | M6: =ROUND((K6*$E$6),0) -> 9263 | O6: yearfemale_nhm | P6: 0.12 | Q6: =LN(1-P6) -> -0.12783337 | R6: =1-EXP(Q6*0.5) -> 0.061916848 | T6: y1female_harv | U6: =(H3-(SUM(U8:U10)))*E10 -> 195.104 | V6: 0.195 | X6: 2029 | Y6: =AB23 -> 48578 | Z6: =ROUND((Y6/Y5),2) -> 0.94
D7: Decimal_Buck | E7: =1 -E6 -> 0.43 | G7: FawnHarvRate | H7: 0.12 | O7: fawnmale_nhm | P7: 0.45 | Q7: =LN(1-P7) -> -0.597837 | R7: =1-EXP(Q7*0.5) -> 0.25838015 | T7: yearmale_harv | U7: =H2*H5 -> 494.45 | V7: =ROUND((U7/L5),2) -> 0.09 | X7: 2030 | Y7: =AB24 -> 45277 | Z7: =ROUND((Y7/Y6),2) -> 0.93
A8: Type | B8: Increased Harvest | O8: fawnfemale_nhm | P8: 0.47 | Q8: =LN(1-P8) -> -0.63487827 | R8: =1-EXP(Q8*0.5) -> 0.27198901 | T8: yearfemale_harv | U8: =H3*H6 -> 1254.24 | V8: 0.255 | X8: 2031 | Y8: =AB25 -> 42166 | Z8: =ROUND((Y8/Y7),2) -> 0.93
D9: Adult prop | E9: 0.51 | O9: 6mofawns_nhm | P9: 0.3 | Q9: =LN(1-P9) -> -0.35667494 | R9: =1-EXP(Q9*0.5) -> 0.16333997 | T9: fawnmale_harv | U9: =H3*(H7/2) -> 418.08 | V9: =ROUND((U9/L6),2) -> 0.06 | X9: 2032 | Y9: =AB26 -> 39219 | Z9: =ROUND((Y9/Y8),2) -> 0.93
D10: Y1 prop | E10: 0.04 | T10: fawnfemale_harv | U10: =H3*(H7/2) -> 418.08 | V10: 0.1 | X10: 2033 | Y10: =AB27 -> 36457 | Z10: =ROUND((Y10/Y9),2) -> 0.93
D11: Yearling prop | E11: 0.2 | X11: 2034 | Y11: =AB28 -> 33878 | Z11: =ROUND((Y11/Y10),2) -> 0.93
D12: Fawn Prop | E12: 0.25 | F12: =SUM(E9:E12) -> 1 | X12: 2035 | Y12: =AB29 -> 31475 | Z12: =ROUND((Y12/Y11),2) -> 0.93
D14: adfemale_preg | E14: 1.6
D15: yfemale_preg | E15: 0.2
B18: Postharvest (January) | K18: Mid-Year (June) | T18: Preharvest (December) | AD18: N_Non-harvest Mortality | AN18: Additional Mortality
A19: Year | B19: N_admale_posth | C19: N_adfemale_posth | D19: N_y1male_posth | E19: N_y1female_posth | F19: N_ymale_posth | G19: N_yfemale_posth | H19: Nfawnmale_posth | I19: N_fawnfemale_posth | J19: N_postharvest | K19: N_admale_mid | L19: N_adfemale_mid | M19: N_y1male_mid | N19: N_y1female_mid | O19: N_ymale_mid | P19: N_yfemale_mid | Q19: birth_malefawn | R19: birth_femalefawn | S19: N_midseason | T19: N_admale_preh | U19: N_adfemale_preh | V19: N_y1male_preh | W19: N_y1female_preh | X19: N_ymale_preh | Y19: N_yfemale_preh | Z19: N_fawnmale_preh | AA19: N_fawnfemale_preh | AB19: N_preharvest | AD19: N_admale_preh | AE19: N_adfemale_preh | AF19: N_y1male_preh | AG19: N_y1female_preh | AH19: N_ymale_preh | AI19: N_yfemale_preh | AJ19: N_fawnmale_preh | AK19: N_fawnfemale_preh | AL19: Total_nhm | AN19: N_admale_addm | AO19: N_adfemale_addm | AP19: N_y1male_addm | AQ19: N_y1female_addm | AR19: N_ymale_addm | AS19: N_yfemale_addm | AT19: Nfawnmale_addm | AU19: N_fawnfemale_addm | AV19: N_addm
A20: 2026 | B20: =ROUND((L3-(L3*V3)),0) -> 10406 | C20: =ROUND((M3-(M3*V4)),0) -> 11810 | D20: =ROUND((L4 - (L4*$V$5)),0) -> 961 | E20: =ROUND((M4 - (M4*$V$6)),0) -> 1193 | F20: =ROUND((L5-(L5*V7)),0) -> 5087 | G20: =ROUND((M5-(M5*V8)),0) -> 5520 | H20: =ROUND((L6 - (L6*V9)),0) -> 6569 | I20: =ROUND((M6 - (M6*$V$10)),0) -> 8337 | J20: =SUM(B20:I20) -> 49883 | K20: =ROUND((B20+D20) - ((B20+D20)*$R$3),0) -> 10167 | L20: =ROUND((C20+E20) - ((C20+E20)*$R$4),0) -> 11417 | M20: =ROUND((F20-(F20*$R$3)),0) -> 4550 | N20: =ROUND((G20-(G20*$R$4)),0) -> 4847 | O20: =ROUND((H20-(H20*$R$7)),0) -> 4872 | P20: =ROUND((I20-(I20*$R$8)),0) -> 6069 | Q20: =ROUND((((L20*$E$14)+(P20*$E$15)+(N20*$E$14))/2),0) -> 13618 | R20: =Q20 -> 13618 | S20: =SUM(K20:R20) -> 69158 | T20: =ROUND(((K20) - ((K20)*$R$3)),0)-AN20 -> 9094 | U20: =ROUND(((L20) - ((L20)*$R$4)),0)-AO20 -> 10025 | V20: =ROUND((M20 -(M20*$R$3)),0)-AP20 -> 4070 | W20: =ROUND((N20 - (N20*$R$4)),0)-AQ20 -> 4256 | X20: =ROUND((O20 - (O20*$R$5)),0)-AR20 -> 4358 | Y20: =ROUND(((P20) - ((P20)*$R$6)),0)-AS20 -> 5693 | Z20: =ROUND((Q20 - (Q20*$R$9)),0)-AT20 -> 11394 | AA20: =ROUND(((R20) - ((R20)*$R$9)),0)-AU20 -> 11394 | AB20: =SUM(T20:AA20) -> 60284 | AD20: =ROUND(((T20+V20)*$R$3)+((K20)*$R$3), 0) -> 2463 | AE20: =ROUND(((U20+W20)*$R$4)+(L20*R4),0) -> 3133 | AF20: =ROUND(((V20)*$R$3)+(M20*$R$3),0) -> 910 | AG20: =ROUND(((W20)*$R$4)+(N20*$R$4),0) -> 1110 | AH20: =ROUND(((X20)*$R$5)+(O20*$R$5),0) -> 974 | AI20: =ROUND(((Y20)*$R$6)+(P20*$R$6),0) -> 728 | AJ20: =ROUND(((Z20)*$R$7)+(Q20*$R$7),0) -> 6463 | AK20: =ROUND(((AA20)*$R$8)+(R20*$R$8),0) -> 6803 | AL20: =SUM(AD20:AK20) -> 22584 | AN20: 0 | AO20: 0 | AP20: 0 | AQ20: 0 | AR20: 0 | AS20: 0 | AT20: 0 | AU20: 0 | AV20: =SUM(AN20:AU20) -> 0
A21: 2027 | B21: =ROUND((T20-(T20*$V$3)),0) -> 6639 | C21: =ROUND((U20-(U20*$V$4)),0) -> 6266 | D21: =ROUND((V20 - (V20*$V$5)),0) -> 3500 | E21: =ROUND((W20 - (W20*$V$6)),0) -> 3426 | F21: =ROUND((X20-(X20*$V$8)),0) -> 3247 | G21: =ROUND((Y20-(Y20*$V$9)),0) -> 5351 | H21: =ROUND((Z20 - (Z20*$V$9)),0) -> 10710 | I21: =ROUND((AA20 - (AA20*$V$10)),0) -> 10255 | J21: =SUM(B21:I21) -> 49394 | K21: =ROUND((B21+D21) - ((B21+D21)*$R$3),0) -> 9069 | L21: =ROUND((C21+E21) - ((C21+E21)*$R$4),0) -> 8510 | M21: =ROUND((F21-(F21*$R$3)),0) -> 2904 | N21: =ROUND((G21-(G21*$R$4)),0) -> 4699 | O21: =ROUND((H21-(H21*$R$7)),0) -> 7943 | P21: =ROUND((I21-(I21*$R$8)),0) -> 7466 | Q21: =ROUND((((L21*$E$14)+(P21*$E$15)+(N21*$E$14))/2),0) -> 11314 | R21: =Q21 -> 11314 | S21: =SUM(K21:R21) -> 63219 | T21: =ROUND(((K21) - ((K21)*$R$3)),0)-AN21 -> 8112 | U21: =ROUND(((L21) - ((L21)*$R$4)),0)-AO21 -> 7472 | V21: =ROUND((M21 -(M21*$R$3)),0)-AP21 -> 2597 | W21: =ROUND((N21 - (N21*$R$4)),0)-AQ21 -> 4126 | X21: =ROUND((O21 - (O21*$R$5)),0)-AR21 -> 7104 | Y21: =ROUND(((P21) - ((P21)*$R$6)),0)-AS21 -> 7004 | Z21: =ROUND((Q21 - (Q21*$R$9)),0)-AT21 -> 9466 | AA21: =ROUND(((R21) - ((R21)*$R$9)),0)-AU21 -> 9466 | AB21: =SUM(T21:AA21) -> 55347 | AD21: =ROUND(((T21+V21)*$R$3)+((K21)*$R$3), 0) -> 2088 | AE21: =ROUND(((U21+W21)*$R$4)+(L21*R5),0) -> 2313 | AF21: =ROUND(((V21)*$R$3)+(M21*$R$3),0) -> 581 | AG21: =ROUND(((W21)*$R$4)+(N21*$R$4),0) -> 1076 | AH21: =ROUND(((X21)*$R$5)+(O21*$R$5),0) -> 1589 | AI21: =ROUND(((Y21)*$R$6)+(P21*$R$6),0) -> 896 | AJ21: =ROUND(((Z21)*$R$7)+(Q21*$R$7),0) -> 5369 | AK21: =ROUND(((AA21)*$R$8)+(R21*$R$8),0) -> 5652 | AL21: =SUM(AD21:AK21) -> 19564 | AN21: 0 | AO21: 0 | AP21: 0 | AQ21: 0 | AR21: 0 | AS21: 0 | AT21: 0 | AU21: 0 | AV21: =SUM(AN21:AU21) -> 0
A22: 2028 | B22: =ROUND((T21-(T21*$V$3)),0) -> 5922 | C22: =ROUND((U21-(U21*$V$4)),0) -> 4670 | D22: =ROUND((V21 - (V21*$V$5)),0) -> 2233 | E22: =ROUND((W21 - (W21*$V$6)),0) -> 3321 | F22: =ROUND((X21-(X21*$V$8)),0) -> 5292 | G22: =ROUND((Y21-(Y21*$V$9)),0) -> 6584 | H22: =ROUND((Z21 - (Z21*$V$9)),0) -> 8898 | I22: =ROUND((AA21 - (AA21*$V$10)),0) -> 8519 | J22: =SUM(B22:I22) -> 45439 | K22: =ROUND((B22+D22) - ((B22+D22)*$R$3),0) -> 7294 | L22: =ROUND((C22+E22) - ((C22+E22)*$R$4),0) -> 7017 | M22: =ROUND((F22-(F22*$R$3)),0) -> 4733 | N22: =ROUND((G22-(G22*$R$4)),0) -> 5781 | O22: =ROUND((H22-(H22*$R$7)),0) -> 6599 | P22: =ROUND((I22-(I22*$R$8)),0) -> 6202 | Q22: =ROUND((((L22*$E$14)+(P22*$E$15)+(N22*$E$14))/2),0) -> 10859 | R22: =Q22 -> 10859 | S22: =SUM(K22:R22) -> 59344 | T22: =ROUND(((K22) - ((K22)*$R$3)),0)-AN22 -> 6524 | U22: =ROUND(((L22) - ((L22)*$R$4)),0)-AO22 -> 6161 | V22: =ROUND((M22 -(M22*$R$3)),0)-AP22 -> 4233 | W22: =ROUND((N22 - (N22*$R$4)),0)-AQ22 -> 5076 | X22: =ROUND((O22 - (O22*$R$5)),0)-AR22 -> 5902 | Y22: =ROUND(((P22) - ((P22)*$R$6)),0)-AS22 -> 5818 | Z22: =ROUND((Q22 - (Q22*$R$9)),0)-AT22 -> 9085 | AA22: =ROUND(((R22) - ((R22)*$R$9)),0)-AU22 -> 9085 | AB22: =SUM(T22:AA22) -> 51884 | AD22: =ROUND(((T22+V22)*$R$3)+((K22)*$R$3), 0) -> 1906 | AE22: =ROUND(((U22+W22)*$R$4)+(L22*R6),0) -> 1805 | AF22: =ROUND(((V22)*$R$3)+(M22*$R$3),0) -> 947 | AG22: =ROUND(((W22)*$R$4)+(N22*$R$4),0) -> 1324 | AH22: =ROUND(((X22)*$R$5)+(O22*$R$5),0) -> 1320 | AI22: =ROUND(((Y22)*$R$6)+(P22*$R$6),0) -> 744 | AJ22: =ROUND(((Z22)*$R$7)+(Q22*$R$7),0) -> 5153 | AK22: =ROUND(((AA22)*$R$8)+(R22*$R$8),0) -> 5425 | AL22: =SUM(AD22:AK22) -> 18624 | AN22: 0 | AO22: 0 | AP22: 0 | AQ22: 0 | AR22: 0 | AS22: 0 | AT22: 0 | AU22: 0 | AV22: =SUM(AN22:AU22) -> 0
A23: 2029 | B23: =ROUND((T22-(T22*$V$3)),0) -> 4763 | C23: =ROUND((U22-(U22*$V$4)),0) -> 3851 | D23: =ROUND((V22 - (V22*$V$5)),0) -> 3640 | E23: =ROUND((W22 - (W22*$V$6)),0) -> 4086 | F23: =ROUND((X22-(X22*$V$8)),0) -> 4397 | G23: =ROUND((Y22-(Y22*$V$9)),0) -> 5469 | H23: =ROUND((Z22 - (Z22*$V$9)),0) -> 8540 | I23: =ROUND((AA22 - (AA22*$V$10)),0) -> 8177 | J23: =SUM(B23:I23) -> 42923 | K23: =ROUND((B23+D23) - ((B23+D23)*$R$3),0) -> 7516 | L23: =ROUND((C23+E23) - ((C23+E23)*$R$4),0) -> 6969 | M23: =ROUND((F23-(F23*$R$3)),0) -> 3933 | N23: =ROUND((G23-(G23*$R$4)),0) -> 4802 | O23: =ROUND((H23-(H23*$R$7)),0) -> 6333 | P23: =ROUND((I23-(I23*$R$8)),0) -> 5953 | Q23: =ROUND((((L23*$E$14)+(P23*$E$15)+(N23*$E$14))/2),0) -> 10012 | R23: =Q23 -> 10012 | S23: =SUM(K23:R23) -> 55530 | T23: =ROUND(((K23) - ((K23)*$R$3)),0)-AN23 -> 6723 | U23: =ROUND(((L23) - ((L23)*$R$4)),0)-AO23 -> 6119 | V23: =ROUND((M23 -(M23*$R$3)),0)-AP23 -> 3518 | W23: =ROUND((N23 - (N23*$R$4)),0)-AQ23 -> 4216 | X23: =ROUND((O23 - (O23*$R$5)),0)-AR23 -> 5664 | Y23: =ROUND(((P23) - ((P23)*$R$6)),0)-AS23 -> 5584 | Z23: =ROUND((Q23 - (Q23*$R$9)),0)-AT23 -> 8377 | AA23: =ROUND(((R23) - ((R23)*$R$9)),0)-AU23 -> 8377 | AB23: =SUM(T23:AA23) -> 48578 | AD23: =ROUND(((T23+V23)*$R$3)+((K23)*$R$3), 0) -> 1875 | AE23: =ROUND(((U23+W23)*$R$4)+(L23*R7),0) -> 3061 | AF23: =ROUND(((V23)*$R$3)+(M23*$R$3),0) -> 787 | AG23: =ROUND(((W23)*$R$4)+(N23*$R$4),0) -> 1100 | AH23: =ROUND(((X23)*$R$5)+(O23*$R$5),0) -> 1267 | AI23: =ROUND(((Y23)*$R$6)+(P23*$R$6),0) -> 714 | AJ23: =ROUND(((Z23)*$R$7)+(Q23*$R$7),0) -> 4751 | AK23: =ROUND(((AA23)*$R$8)+(R23*$R$8),0) -> 5002 | AL23: =SUM(AD23:AK23) -> 18557 | AN23: 0 | AO23: 0 | AP23: 0 | AQ23: 0 | AR23: 0 | AS23: 0 | AT23: 0 | AU23: 0 | AV23: =SUM(AN23:AU23) -> 0
A24: 2030 | B24: =ROUND((T23-(T23*$V$3)),0) -> 4908 | C24: =ROUND((U23-(U23*$V$4)),0) -> 3824 | D24: =ROUND((V23 - (V23*$V$5)),0) -> 3025 | E24: =ROUND((W23 - (W23*$V$6)),0) -> 3394 | F24: =ROUND((X23-(X23*$V$8)),0) -> 4220 | G24: =ROUND((Y23-(Y23*$V$9)),0) -> 5249 | H24: =ROUND((Z23 - (Z23*$V$9)),0) -> 7874 | I24: =ROUND((AA23 - (AA23*$V$10)),0) -> 7539 | J24: =SUM(B24:I24) -> 40033 | K24: =ROUND((B24+D24) - ((B24+D24)*$R$3),0) -> 7095 | L24: =ROUND((C24+E24) - ((C24+E24)*$R$4),0) -> 6338 | M24: =ROUND((F24-(F24*$R$3)),0) -> 3774 | N24: =ROUND((G24-(G24*$R$4)),0) -> 4609 | O24: =ROUND((H24-(H24*$R$7)),0) -> 5840 | P24: =ROUND((I24-(I24*$R$8)),0) -> 5488 | Q24: =ROUND((((L24*$E$14)+(P24*$E$15)+(N24*$E$14))/2),0) -> 9306 | R24: =Q24 -> 9306 | S24: =SUM(K24:R24) -> 51756 | T24: =ROUND(((K24) - ((K24)*$R$3)),0)-AN24 -> 6346 | U24: =ROUND(((L24) - ((L24)*$R$4)),0)-AO24 -> 5565 | V24: =ROUND((M24 -(M24*$R$3)),0)-AP24 -> 3376 | W24: =ROUND((N24 - (N24*$R$4)),0)-AQ24 -> 4047 | X24: =ROUND((O24 - (O24*$R$5)),0)-AR24 -> 5223 | Y24: =ROUND(((P24) - ((P24)*$R$6)),0)-AS24 -> 5148 | Z24: =ROUND((Q24 - (Q24*$R$9)),0)-AT24 -> 7786 | AA24: =ROUND(((R24) - ((R24)*$R$9)),0)-AU24 -> 7786 | AB24: =SUM(T24:AA24) -> 45277 | AD24: =ROUND(((T24+V24)*$R$3)+((K24)*$R$3), 0) -> 1775 | AE24: =ROUND(((U24+W24)*$R$4)+(L24*R8),0) -> 2896 | AF24: =ROUND(((V24)*$R$3)+(M24*$R$3),0) -> 755 | AG24: =ROUND(((W24)*$R$4)+(N24*$R$4),0) -> 1055 | AH24: =ROUND(((X24)*$R$5)+(O24*$R$5),0) -> 1168 | AI24: =ROUND(((Y24)*$R$6)+(P24*$R$6),0) -> 659 | AJ24: =ROUND(((Z24)*$R$7)+(Q24*$R$7),0) -> 4416 | AK24: =ROUND(((AA24)*$R$8)+(R24*$R$8),0) -> 4649 | AL24: =SUM(AD24:AK24) -> 17373 | AN24: 0 | AO24: 0 | AP24: 0 | AQ24: 0 | AR24: 0 | AS24: 0 | AT24: 0 | AU24: 0 | AV24: =SUM(AN24:AU24) -> 0
A25: 2031 | B25: =ROUND((T24-(T24*$V$3)),0) -> 4633 | C25: =ROUND((U24-(U24*$V$4)),0) -> 3478 | D25: =ROUND((V24 - (V24*$V$5)),0) -> 2903 | E25: =ROUND((W24 - (W24*$V$6)),0) -> 3258 | F25: =ROUND((X24-(X24*$V$8)),0) -> 3891 | G25: =ROUND((Y24-(Y24*$V$9)),0) -> 4839 | H25: =ROUND((Z24 - (Z24*$V$9)),0) -> 7319 | I25: =ROUND((AA24 - (AA24*$V$10)),0) -> 7007 | J25: =SUM(B25:I25) -> 37328 | K25: =ROUND((B25+D25) - ((B25+D25)*$R$3),0) -> 6740 | L25: =ROUND((C25+E25) - ((C25+E25)*$R$4),0) -> 5915 | M25: =ROUND((F25-(F25*$R$3)),0) -> 3480 | N25: =ROUND((G25-(G25*$R$4)),0) -> 4249 | O25: =ROUND((H25-(H25*$R$7)),0) -> 5428 | P25: =ROUND((I25-(I25*$R$8)),0) -> 5101 | Q25: =ROUND((((L25*$E$14)+(P25*$E$15)+(N25*$E$14))/2),0) -> 8641 | R25: =Q25 -> 8641 | S25: =SUM(K25:R25) -> 48195 | T25: =ROUND(((K25) - ((K25)*$R$3)),0)-AN25 -> 6028 | U25: =ROUND(((L25) - ((L25)*$R$4)),0)-AO25 -> 5194 | V25: =ROUND((M25 -(M25*$R$3)),0)-AP25 -> 3113 | W25: =ROUND((N25 - (N25*$R$4)),0)-AQ25 -> 3731 | X25: =ROUND((O25 - (O25*$R$5)),0)-AR25 -> 4855 | Y25: =ROUND(((P25) - ((P25)*$R$6)),0)-AS25 -> 4785 | Z25: =ROUND((Q25 - (Q25*$R$9)),0)-AT25 -> 7230 | AA25: =ROUND(((R25) - ((R25)*$R$9)),0)-AU25 -> 7230 | AB25: =SUM(T25:AA25) -> 42166 | AD25: =ROUND(((T25+V25)*$R$3)+((K25)*$R$3), 0) -> 1677 | AE25: =ROUND(((U25+W25)*$R$4)+(L25*R9),0) -> 2054 | AF25: =ROUND(((V25)*$R$3)+(M25*$R$3),0) -> 696 | AG25: =ROUND(((W25)*$R$4)+(N25*$R$4),0) -> 973 | AH25: =ROUND(((X25)*$R$5)+(O25*$R$5),0) -> 1086 | AI25: =ROUND(((Y25)*$R$6)+(P25*$R$6),0) -> 612 | AJ25: =ROUND(((Z25)*$R$7)+(Q25*$R$7),0) -> 4101 | AK25: =ROUND(((AA25)*$R$8)+(R25*$R$8),0) -> 4317 | AL25: =SUM(AD25:AK25) -> 15516 | AN25: 0 | AO25: 0 | AP25: 0 | AQ25: 0 | AR25: 0 | AS25: 0 | AT25: 0 | AU25: 0 | AV25: =SUM(AN25:AU25) -> 0
A26: 2032 | B26: =ROUND((T25-(T25*$V$3)),0) -> 4400 | C26: =ROUND((U25-(U25*$V$4)),0) -> 3246 | D26: =ROUND((V25 - (V25*$V$5)),0) -> 2677 | E26: =ROUND((W25 - (W25*$V$6)),0) -> 3003 | F26: =ROUND((X25-(X25*$V$8)),0) -> 3617 | G26: =ROUND((Y25-(Y25*$V$9)),0) -> 4498 | H26: =ROUND((Z25 - (Z25*$V$9)),0) -> 6796 | I26: =ROUND((AA25 - (AA25*$V$10)),0) -> 6507 | J26: =SUM(B26:I26) -> 34744 | K26: =ROUND((B26+D26) - ((B26+D26)*$R$3),0) -> 6330 | L26: =ROUND((C26+E26) - ((C26+E26)*$R$4),0) -> 5487 | M26: =ROUND((F26-(F26*$R$3)),0) -> 3235 | N26: =ROUND((G26-(G26*$R$4)),0) -> 3950 | O26: =ROUND((H26-(H26*$R$7)),0) -> 5040 | P26: =ROUND((I26-(I26*$R$8)),0) -> 4737 | Q26: =ROUND((((L26*$E$14)+(P26*$E$15)+(N26*$E$14))/2),0) -> 8023 | R26: =Q26 -> 8023 | S26: =SUM(K26:R26) -> 44825 | T26: =ROUND(((K26) - ((K26)*$R$3)),0)-AN26 -> 5662 | U26: =ROUND(((L26) - ((L26)*$R$4)),0)-AO26 -> 4818 | V26: =ROUND((M26 -(M26*$R$3)),0)-AP26 -> 2893 | W26: =ROUND((N26 - (N26*$R$4)),0)-AQ26 -> 3468 | X26: =ROUND((O26 - (O26*$R$5)),0)-AR26 -> 4508 | Y26: =ROUND(((P26) - ((P26)*$R$6)),0)-AS26 -> 4444 | Z26: =ROUND((Q26 - (Q26*$R$9)),0)-AT26 -> 6713 | AA26: =ROUND(((R26) - ((R26)*$R$9)),0)-AU26 -> 6713 | AB26: =SUM(T26:AA26) -> 39219 | AD26: =ROUND(((T26+V26)*$R$3)+((K26)*$R$3), 0) -> 1571 | AE26: =ROUND(((U26+W26)*$R$4)+(L26*R10),0) -> 1010 | AF26: =ROUND(((V26)*$R$3)+(M26*$R$3),0) -> 647 | AG26: =ROUND(((W26)*$R$4)+(N26*$R$4),0) -> 905 | AH26: =ROUND(((X26)*$R$5)+(O26*$R$5),0) -> 1008 | AI26: =ROUND(((Y26)*$R$6)+(P26*$R$6),0) -> 568 | AJ26: =ROUND(((Z26)*$R$7)+(Q26*$R$7),0) -> 3807 | AK26: =ROUND(((AA26)*$R$8)+(R26*$R$8),0) -> 4008 | AL26: =SUM(AD26:AK26) -> 13524 | AN26: 0 | AO26: 0 | AP26: 0 | AQ26: 0 | AR26: 0 | AS26: 0 | AT26: 0 | AU26: 0 | AV26: =SUM(AN26:AU26) -> 0
A27: 2033 | B27: =ROUND((T26-(T26*$V$3)),0) -> 4133 | C27: =ROUND((U26-(U26*$V$4)),0) -> 3011 | D27: =ROUND((V26 - (V26*$V$5)),0) -> 2488 | E27: =ROUND((W26 - (W26*$V$6)),0) -> 2792 | F27: =ROUND((X26-(X26*$V$8)),0) -> 3358 | G27: =ROUND((Y26-(Y26*$V$9)),0) -> 4177 | H27: =ROUND((Z26 - (Z26*$V$9)),0) -> 6310 | I27: =ROUND((AA26 - (AA26*$V$10)),0) -> 6042 | J27: =SUM(B27:I27) -> 32311 | K27: =ROUND((B27+D27) - ((B27+D27)*$R$3),0) -> 5922 | L27: =ROUND((C27+E27) - ((C27+E27)*$R$4),0) -> 5095 | M27: =ROUND((F27-(F27*$R$3)),0) -> 3003 | N27: =ROUND((G27-(G27*$R$4)),0) -> 3668 | O27: =ROUND((H27-(H27*$R$7)),0) -> 4680 | P27: =ROUND((I27-(I27*$R$8)),0) -> 4399 | Q27: =ROUND((((L27*$E$14)+(P27*$E$15)+(N27*$E$14))/2),0) -> 7450 | R27: =Q27 -> 7450 | S27: =SUM(K27:R27) -> 41667 | T27: =ROUND(((K27) - ((K27)*$R$3)),0)-AN27 -> 5297 | U27: =ROUND(((L27) - ((L27)*$R$4)),0)-AO27 -> 4474 | V27: =ROUND((M27 -(M27*$R$3)),0)-AP27 -> 2686 | W27: =ROUND((N27 - (N27*$R$4)),0)-AQ27 -> 3221 | X27: =ROUND((O27 - (O27*$R$5)),0)-AR27 -> 4186 | Y27: =ROUND(((P27) - ((P27)*$R$6)),0)-AS27 -> 4127 | Z27: =ROUND((Q27 - (Q27*$R$9)),0)-AT27 -> 6233 | AA27: =ROUND(((R27) - ((R27)*$R$9)),0)-AU27 -> 6233 | AB27: =SUM(T27:AA27) -> 36457 | AD27: =ROUND(((T27+V27)*$R$3)+((K27)*$R$3), 0) -> 1468 | AE27: =ROUND(((U27+W27)*$R$4)+(L27*R11),0) -> 938 | AF27: =ROUND(((V27)*$R$3)+(M27*$R$3),0) -> 601 | AG27: =ROUND(((W27)*$R$4)+(N27*$R$4),0) -> 840 | AH27: =ROUND(((X27)*$R$5)+(O27*$R$5),0) -> 936 | AI27: =ROUND(((Y27)*$R$6)+(P27*$R$6),0) -> 528 | AJ27: =ROUND(((Z27)*$R$7)+(Q27*$R$7),0) -> 3535 | AK27: =ROUND(((AA27)*$R$8)+(R27*$R$8),0) -> 3722 | AL27: =SUM(AD27:AK27) -> 12568 | AN27: 0 | AO27: 0 | AP27: 0 | AQ27: 0 | AR27: 0 | AS27: 0 | AT27: 0 | AU27: 0 | AV27: =SUM(AN27:AU27) -> 0
A28: 2034 | B28: =ROUND((T27-(T27*$V$3)),0) -> 3867 | C28: =ROUND((U27-(U27*$V$4)),0) -> 2796 | D28: =ROUND((V27 - (V27*$V$5)),0) -> 2310 | E28: =ROUND((W27 - (W27*$V$6)),0) -> 2593 | F28: =ROUND((X27-(X27*$V$8)),0) -> 3119 | G28: =ROUND((Y27-(Y27*$V$9)),0) -> 3879 | H28: =ROUND((Z27 - (Z27*$V$9)),0) -> 5859 | I28: =ROUND((AA27 - (AA27*$V$10)),0) -> 5610 | J28: =SUM(B28:I28) -> 30033 | K28: =ROUND((B28+D28) - ((B28+D28)*$R$3),0) -> 5525 | L28: =ROUND((C28+E28) - ((C28+E28)*$R$4),0) -> 4732 | M28: =ROUND((F28-(F28*$R$3)),0) -> 2790 | N28: =ROUND((G28-(G28*$R$4)),0) -> 3406 | O28: =ROUND((H28-(H28*$R$7)),0) -> 4345 | P28: =ROUND((I28-(I28*$R$8)),0) -> 4084 | Q28: =ROUND((((L28*$E$14)+(P28*$E$15)+(N28*$E$14))/2),0) -> 6919 | R28: =Q28 -> 6919 | S28: =SUM(K28:R28) -> 38720 | T28: =ROUND(((K28) - ((K28)*$R$3)),0)-AN28 -> 4942 | U28: =ROUND(((L28) - ((L28)*$R$4)),0)-AO28 -> 4155 | V28: =ROUND((M28 -(M28*$R$3)),0)-AP28 -> 2495 | W28: =ROUND((N28 - (N28*$R$4)),0)-AQ28 -> 2991 | X28: =ROUND((O28 - (O28*$R$5)),0)-AR28 -> 3886 | Y28: =ROUND(((P28) - ((P28)*$R$6)),0)-AS28 -> 3831 | Z28: =ROUND((Q28 - (Q28*$R$9)),0)-AT28 -> 5789 | AA28: =ROUND(((R28) - ((R28)*$R$9)),0)-AU28 -> 5789 | AB28: =SUM(T28:AA28) -> 33878 | AD28: =ROUND(((T28+V28)*$R$3)+((K28)*$R$3), 0) -> 1368 | AE28: =ROUND(((U28+W28)*$R$4)+(L28*R12),0) -> 871 | AF28: =ROUND(((V28)*$R$3)+(M28*$R$3),0) -> 558 | AG28: =ROUND(((W28)*$R$4)+(N28*$R$4),0) -> 780 | AH28: =ROUND(((X28)*$R$5)+(O28*$R$5),0) -> 869 | AI28: =ROUND(((Y28)*$R$6)+(P28*$R$6),0) -> 490 | AJ28: =ROUND(((Z28)*$R$7)+(Q28*$R$7),0) -> 3283 | AK28: =ROUND(((AA28)*$R$8)+(R28*$R$8),0) -> 3456 | AL28: =SUM(AD28:AK28) -> 11675 | AN28: 0 | AO28: 0 | AP28: 0 | AQ28: 0 | AR28: 0 | AS28: 0 | AT28: 0 | AU28: 0 | AV28: =SUM(AN28:AU28) -> 0
A29: 2035 | B29: =ROUND((T28-(T28*$V$3)),0) -> 3608 | C29: =ROUND((U28-(U28*$V$4)),0) -> 2597 | D29: =ROUND((V28 - (V28*$V$5)),0) -> 2146 | E29: =ROUND((W28 - (W28*$V$6)),0) -> 2408 | F29: =ROUND((X28-(X28*$V$8)),0) -> 2895 | G29: =ROUND((Y28-(Y28*$V$9)),0) -> 3601 | H29: =ROUND((Z28 - (Z28*$V$9)),0) -> 5442 | I29: =ROUND((AA28 - (AA28*$V$10)),0) -> 5210 | J29: =SUM(B29:I29) -> 27907 | K29: =ROUND((B29+D29) - ((B29+D29)*$R$3),0) -> 5147 | L29: =ROUND((C29+E29) - ((C29+E29)*$R$4),0) -> 4395 | M29: =ROUND((F29-(F29*$R$3)),0) -> 2589 | N29: =ROUND((G29-(G29*$R$4)),0) -> 3162 | O29: =ROUND((H29-(H29*$R$7)),0) -> 4036 | P29: =ROUND((I29-(I29*$R$8)),0) -> 3793 | Q29: =ROUND((((L29*$E$14)+(P29*$E$15)+(N29*$E$14))/2),0) -> 6425 | R29: =Q29 -> 6425 | S29: =SUM(K29:R29) -> 35972 | T29: =ROUND(((K29) - ((K29)*$R$3)),0)-AN29 -> 4604 | U29: =ROUND(((L29) - ((L29)*$R$4)),0)-AO29 -> 3859 | V29: =ROUND((M29 -(M29*$R$3)),0)-AP29 -> 2316 | W29: =ROUND((N29 - (N29*$R$4)),0)-AQ29 -> 2776 | X29: =ROUND((O29 - (O29*$R$5)),0)-AR29 -> 3610 | Y29: =ROUND(((P29) - ((P29)*$R$6)),0)-AS29 -> 3558 | Z29: =ROUND((Q29 - (Q29*$R$9)),0)-AT29 -> 5376 | AA29: =ROUND(((R29) - ((R29)*$R$9)),0)-AU29 -> 5376 | AB29: =SUM(T29:AA29) -> 31475 | AD29: =ROUND(((T29+V29)*$R$3)+((K29)*$R$3), 0) -> 1274 | AE29: =ROUND(((U29+W29)*$R$4)+(L29*R13),0) -> 809 | AF29: =ROUND(((V29)*$R$3)+(M29*$R$3),0) -> 518 | AG29: =ROUND(((W29)*$R$4)+(N29*$R$4),0) -> 724 | AH29: =ROUND(((X29)*$R$5)+(O29*$R$5),0) -> 807 | AI29: =ROUND(((Y29)*$R$6)+(P29*$R$6),0) -> 455 | AJ29: =ROUND(((Z29)*$R$7)+(Q29*$R$7),0) -> 3049 | AK29: =ROUND(((AA29)*$R$8)+(R29*$R$8),0) -> 3210 | AL29: =SUM(AD29:AK29) -> 10846 | AN29: 0 | AO29: 0 | AP29: 0 | AQ29: 0 | AR29: 0 | AS29: 0 | AT29: 0 | AU29: 0 | AV29: =SUM(AN29:AU29) -> 0
A31: Modeled Harvest Projections | L31: Combined Age Classes
B32: Model_Harvest | C32: Model_harvest_adM | D32: Model_harvest_adF | E32: Model_harvest_y1M | F32: Model_harvest_y1F | G32: Model_harvest_yM | H32: Model_harvest_yF | I32: Model_harvest_fawnM | J32: Model_harvest_fawnF | M32: N_CFawn | N32: N_Cyear | O32: N_CY1 | P32: N_Cadult
A33: 2026 | B33: =SUM(C33:J33) -> 10890 | C33: =T20-B21 -> 2455 | D33: =U20-C21 -> 3759 | E33: =V20-D21 -> 570 | F33: =W20-E21 -> 830 | G33: =X20-F21 -> 1111 | H33: =Y20-G21 -> 342 | I33: =Z20-H21 -> 684 | J33: =AA20-I21 -> 1139 | L33: 2026 | M33: =AA20+Z20 -> 22788 | N33: =Y20+X20 -> 10051 | O33: =W20+V20 -> 8326 | P33: =U20+T20 -> 19119
A34: 2027 | B34: =SUM(C34:J34) -> 9908 | C34: =T21-B22 -> 2190 | D34: =U21-C22 -> 2802 | E34: =V21-D22 -> 364 | F34: =W21-E22 -> 805 | G34: =X21-F22 -> 1812 | H34: =Y21-G22 -> 420 | I34: =Z21-H22 -> 568 | J34: =AA21-I22 -> 947 | L34: 2027 | M34: =AA21+Z21 -> 18932 | N34: =Y21+X21 -> 14108 | O34: =W21+V21 -> 6723 | P34: =U21+T21 -> 15584
A35: 2028 | B35: =SUM(C35:J35) -> 8961 | C35: =T22-B23 -> 1761 | D35: =U22-C23 -> 2310 | E35: =V22-D23 -> 593 | F35: =W22-E23 -> 990 | G35: =X22-F23 -> 1505 | H35: =Y22-G23 -> 349 | I35: =Z22-H23 -> 545 | J35: =AA22-I23 -> 908 | L35: 2028 | M35: =AA22+Z22 -> 18170 | N35: =Y22+X22 -> 11720 | O35: =W22+V22 -> 9309 | P35: =U22+T22 -> 12685
A36: 2029 | B36: =SUM(C36:J36) -> 8545 | C36: =T23-B24 -> 1815 | D36: =U23-C24 -> 2295 | E36: =V23-D24 -> 493 | F36: =W23-E24 -> 822 | G36: =X23-F24 -> 1444 | H36: =Y23-G24 -> 335 | I36: =Z23-H24 -> 503 | J36: =AA23-I24 -> 838 | L36: 2029 | M36: =AA23+Z23 -> 16754 | N36: =Y23+X23 -> 11248 | O36: =W23+V23 -> 7734 | P36: =U23+T23 -> 12842
A37: 2030 | B37: =SUM(C37:J37) -> 7949 | C37: =T24-B25 -> 1713 | D37: =U24-C25 -> 2087 | E37: =V24-D25 -> 473 | F37: =W24-E25 -> 789 | G37: =X24-F25 -> 1332 | H37: =Y24-G25 -> 309 | I37: =Z24-H25 -> 467 | J37: =AA24-I25 -> 779 | L37: 2030 | M37: =AA24+Z24 -> 15572 | N37: =Y24+X24 -> 10371 | O37: =W24+V24 -> 7423 | P37: =U24+T24 -> 11911
A38: 2031 | B38: =SUM(C38:J38) -> 7422 | C38: =T25-B26 -> 1628 | D38: =U25-C26 -> 1948 | E38: =V25-D26 -> 436 | F38: =W25-E26 -> 728 | G38: =X25-F26 -> 1238 | H38: =Y25-G26 -> 287 | I38: =Z25-H26 -> 434 | J38: =AA25-I26 -> 723 | L38: 2031 | M38: =AA25+Z25 -> 14460 | N38: =Y25+X25 -> 9640 | O38: =W25+V25 -> 6844 | P38: =U25+T25 -> 11222
A39: 2032 | B39: =SUM(C39:J39) -> 6908 | C39: =T26-B27 -> 1529 | D39: =U26-C27 -> 1807 | E39: =V26-D27 -> 405 | F39: =W26-E27 -> 676 | G39: =X26-F27 -> 1150 | H39: =Y26-G27 -> 267 | I39: =Z26-H27 -> 403 | J39: =AA26-I27 -> 671 | L39: 2032 | M39: =AA26+Z26 -> 13426 | N39: =Y26+X26 -> 8952 | O39: =W26+V26 -> 6361 | P39: =U26+T26 -> 10480
A40: 2033 | B40: =SUM(C40:J40) -> 6424 | C40: =T27-B28 -> 1430 | D40: =U27-C28 -> 1678 | E40: =V27-D28 -> 376 | F40: =W27-E28 -> 628 | G40: =X27-F28 -> 1067 | H40: =Y27-G28 -> 248 | I40: =Z27-H28 -> 374 | J40: =AA27-I28 -> 623 | L40: 2033 | M40: =AA27+Z27 -> 12466 | N40: =Y27+X27 -> 8313 | O40: =W27+V27 -> 5907 | P40: =U27+T27 -> 9771
A41: 2034 | B41: =SUM(C41:J41) -> 5971 | C41: =T28-B29 -> 1334 | D41: =U28-C29 -> 1558 | E41: =V28-D29 -> 349 | F41: =W28-E29 -> 583 | G41: =X28-F29 -> 991 | H41: =Y28-G29 -> 230 | I41: =Z28-H29 -> 347 | J41: =AA28-I29 -> 579 | L41: 2034 | M41: =AA28+Z28 -> 11578 | N41: =Y28+X28 -> 7717 | O41: =W28+V28 -> 5486 | P41: =U28+T28 -> 9097
A42: 2035 | B42: na | C42: na | D42: na | E42: na | F42: na | G42: na | H42: na | I42: na | J42: na | L42: 2035 | M42: =AA29+Z29 -> 10752 | N42: =Y29+X29 -> 7168 | O42: =W29+V29 -> 5092 | P42: =U29+T29 -> 8463
A44: Modeled Harvest Averages
B45: Male | C45: Female
...

Sheet ForAnalysis
A1: Year | B1: N_admale_posth | C1: N_adfemale_posth | D1: N_y1male_posth | E1: N_y1female_posth | F1: N_ymale_posth | G1: N_yfemale_posth | H1: Nfawnmale_posth | I1: N_fawnfemale_posth | J1: N_postharvest | K1: N_admale_mid | L1: N_adfemale_mid | M1: N_y1male_mid | N1: N_y1female_mid | O1: N_ymale_mid | P1: N_yfemale_mid | Q1: birth_malefawn | R1: birth_femalefawn | S1: N_midseason | T1: N_admale_preh | U1: N_adfemale_preh | V1: N_y1male_preh | W1: N_y1female_preh | X1: N_ymale_preh | Y1: N_yfemale_preh | Z1: N_fawnmale_preh | AA1: N_fawnfemale_preh | AB1: N_preharvest | AC1: Model_Harvest | AD1: Model_harvest_adM | AE1: Model_harvest_adF | AF1: Model_harvest_y1M | AG1: Model_harvest_y1F | AH1: Model_harvest_yM | AI1: Model_harvest_yF | AJ1: Model_harvest_fawnM | AK1: Model_harvest_fawnF | AL1: N_CFawn | AM1: N_Cyear | AN1: N_CY1 | AO1: N_Cadult | AP1: Lambda | AQ1: County | AR1: Type
A2: {='AcCountDeer(Initial)'!A20:AB29} -> 2026 | B2: 10406 | C2: 14172 | D2: 961 | E2: 1289 | F2: 5087 | G2: 6150 | H2: 6569 | I2: 8800 | J2: 53434 | K2: 10167 | L2: 13576 | M2: 4550 | N2: 5400 | O2: 4872 | P2: 6406 | Q2: 15821 | R2: 15821 | S2: 76613 | T2: 9094 | U2: 11921 | V2: 4070 | W2: 4742 | X2: 4358 | Y2: 6009 | Z2: 13237 | AA2: 13237 | AB2: 66668 | AC2: {='AcCountDeer(Initial)'!B33:J42} -> 9179 | AD2: 2455 | AE2: 2980 | AF2: 570 | AG2: 616 | AH2: 741 | AI2: 361 | AJ2: 794 | AK2: 662 | AL2: {='AcCountDeer(Initial)'!M33:P42} -> 26474 | AM2: 10367 | AN2: 8812 | AO2: 21015 | AP2: {='AcCountDeer(Initial)'!Z3:Z12} -> NA | AQ2: ='AcCountDeer(Initial)'!B2 -> Baldwin | AR2: ='AcCountDeer(Initial)'!B8 -> Baseline
A3: 2027 | B3: 6639 | C3: 8941 | D3: 3500 | E3: 4126 | F3: 3617 | G3: 5648 | H3: 12443 | I3: 12575 | J3: 57489 | K3: 9069 | L3: 11474 | M3: 3235 | N3: 4959 | O3: 9228 | P3: 9155 | Q3: 14062 | R3: 14062 | S3: 75244 | T3: 8112 | U3: 10075 | V3: 2893 | W3: 4354 | X3: 8254 | Y3: 8588 | Z3: 11765 | AA3: 11765 | AB3: 65806 | AC3: 8892 | AD3: 2190 | AE3: 2519 | AF3: 405 | AG3: 566 | AH3: 1403 | AI3: 515 | AJ3: 706 | AK3: 588 | AL3: 23530 | AM3: 16842 | AN3: 7247 | AO3: 18187 | AP3: 0.99 | AQ3: =$AQ$2 -> Baldwin | AR3: =$AR$2 -> Baseline
A4: 2028 | B4: 5922 | C4: 7556 | D4: 2488 | E4: 3788 | F4: 6851 | G4: 8073 | H4: 11059 | I4: 11177 | J4: 56914 | K4: 7522 | L4: 9961 | M4: 6128 | N4: 7089 | O4: 8202 | P4: 8137 | Q4: 14454 | R4: 14454 | S4: 75947 | T4: 6728 | U4: 8746 | V4: 5481 | W4: 6225 | X4: 7336 | Y4: 7633 | Z4: 12093 | AA4: 12093 | AB4: 66335 | AC4: 8615 | AD4: 1817 | AE4: 2186 | AF4: 767 | AG4: 809 | AH4: 1247 | AI4: 458 | AJ4: 726 | AK4: 605 | AL4: 24186 | AM4: 14969 | AN4: 11706 | AO4: 15474 | AP4: 1.01 | AQ4: =$AQ$2 -> Baldwin | AR4: =$AR$2 -> Baseline
A5: 2029 | B5: 4911 | C5: 6560 | D5: 4714 | E5: 5416 | F5: 6089 | G5: 7175 | H5: 11367 | I5: 11488 | J5: 57720 | K5: 8609 | L5: 10516 | M5: 5446 | N5: 6300 | O5: 8430 | P5: 8363 | Q5: 14289 | R5: 14289 | S5: 76242 | T5: 7700 | U5: 9234 | V5: 4871 | W5: 5532 | X5: 7540 | Y5: 7845 | Z5: 11955 | AA5: 11955 | AB5: 66632 | AC5: 8856 | AD5: 2079 | AE5: 2308 | AF5: 682 | AG5: 719 | AH5: 1282 | AI5: 471 | AJ5: 717 | AK5: 598 | AL5: 23910 | AM5: 15385 | AN5: 10403 | AO5: 16934 | AP5: 1 | AQ5: =$AQ$2 -> Baldwin | AR5: =$AR$2 -> Baseline
A6: 2030 | B6: 5621 | C6: 6926 | D6: 4189 | E6: 4813 | F6: 6258 | G6: 7374 | H6: 11238 | I6: 11357 | J6: 57776 | K6: 8774 | L6: 10308 | M6: 5597 | N6: 6475 | O6: 8334 | P6: 8268 | Q6: 14253 | R6: 14253 | S6: 76262 | T6: 7848 | U6: 9051 | V6: 5006 | W6: 5685 | X6: 7454 | Y6: 7756 | Z6: 11925 | AA6: 11925 | AB6: 66650 | AC6: 8865 | AD6: 2119 | AE6: 2263 | AF6: 701 | AG6: 739 | AH6: 1267 | AI6: 465 | AJ6: 715 | AK6: 596 | AL6: 23850 | AM6: 15210 | AN6: 10691 | AO6: 16899 | AP6: 1 | AQ6: =$AQ$2 -> Baldwin | AR6: =$AR$2 -> Baseline
A7: 2031 | B7: 5729 | C7: 6788 | D7: 4305 | E7: 4946 | F7: 6187 | G7: 7291 | H7: 11210 | I7: 11329 | J7: 57785 | K7: 8975 | L7: 10303 | M7: 5534 | N7: 6402 | O7: 8314 | P7: 8248 | Q7: 14189 | R7: 14189 | S7: 76154 | T7: 8027 | U7: 9047 | V7: 4950 | W7: 5621 | X7: 7436 | Y7: 7737 | Z7: 11871 | AA7: 11871 | AB7: 66560 | AC7: 8887 | AD7: 2167 | AE7: 2262 | AF7: 693 | AG7: 731 | AH7: 1264 | AI7: 464 | AJ7: 712 | AK7: 594 | AL7: 23742 | AM7: 15173 | AN7: 10571 | AO7: 17074 | AP7: 1 | AQ7: =$AQ$2 -> Baldwin | AR7: =$AR$2 -> Baseline
A8: 2032 | B8: 5860 | C8: 6785 | D8: 4257 | E8: 4890 | F8: 6172 | G8: 7273 | H8: 11159 | I8: 11277 | J8: 57673 | K8: 9049 | L8: 10251 | M8: 5520 | N8: 6386 | O8: 8276 | P8: 8210 | Q8: 14131 | R8: 14131 | S8: 75954 | T8: 8094 | U8: 9001 | V8: 4937 | W8: 5607 | X8: 7402 | Y8: 7702 | Z8: 11823 | AA8: 11823 | AB8: 66389 | AC8: 8875 | AD8: 2185 | AE8: 2250 | AF8: 691 | AG8: 729 | AH8: 1258 | AI8: 462 | AJ8: 709 | AK8: 591 | AL8: 23646 | AM8: 15104 | AN8: 10544 | AO8: 17095 | AP8: 1 | AQ8: =$AQ$2 -> Baldwin | AR8: =$AR$2 -> Baseline
A9: 2033 | B9: 5909 | C9: 6751 | D9: 4246 | E9: 4878 | F9: 6144 | G9: 7240 | H9: 11114 | I9: 11232 | J9: 57514 | K9: 9083 | L9: 10211 | M9: 5495 | N9: 6357 | O9: 8242 | P9: 8177 | Q9: 14072 | R9: 14072 | S9: 75709 | T9: 8124 | U9: 8966 | V9: 4915 | W9: 5582 | X9: 7372 | Y9: 7671 | Z9: 11773 | AA9: 11773 | AB9: 66176 | AC9: 8856 | AD9: 2193 | AE9: 2241 | AF9: 688 | AG9: 726 | AH9: 1253 | AI9: 460 | AJ9: 706 | AK9: 589 | AL9: 23546 | AM9: 15043 | AN9: 10497 | AO9: 17090 | AP9: 1 | AQ9: =$AQ$2 -> Baldwin | AR9: =$AR$2 -> Baseline
A10: 2034 | B10: 5931 | C10: 6725 | D10: 4227 | E10: 4856 | F10: 6119 | G10: 7211 | H10: 11067 | I10: 11184 | J10: 57320 | K10: 9086 | L10: 10169 | M10: 5473 | N10: 6332 | O10: 8208 | P10: 8142 | Q10: 14015 | R10: 14015 | S10: 75440 | T10: 8127 | U10: 8929 | V10: 4895 | W10: 5560 | X10: 7341 | Y10: 7638 | Z10: 11726 | AA10: 11726 | AB10: 65942 | AC10: 8830 | AD10: 2194 | AE10: 2232 | AF10: 685 | AG10: 723 | AH10: 1248 | AI10: 458 | AJ10: 704 | AK10: 586 | AL10: 23452 | AM10: 14979 | AN10: 10455 | AO10: 17056 | AP10: 1 | AQ10: =$AQ$2 -> Baldwin | AR10: =$AR$2 -> Baseline
A11: 2035 | B11: 5933 | C11: 6697 | D11: 4210 | E11: 4837 | F11: 6093 | G11: 7180 | H11: 11022 | I11: 11140 | J11: 57112 | K11: 9072 | L11: 10128 | M11: 5450 | N11: 6305 | O11: 8174 | P11: 8110 | Q11: 13957 | R11: 13957 | S11: 75153 | T11: 8114 | U11: 8893 | V11: 4875 | W11: 5536 | X11: 7311 | Y11: 7608 | Z11: 11677 | AA11: 11677 | AB11: 65691 | AC11: na | AD11: na | AE11: na | AF11: na | AG11: na | AH11: na | AI11: na | AJ11: na | AK11: na | AL11: 23354 | AM11: 14919 | AN11: 10411 | AO11: 17007 | AP11: 1 | AQ11: =$AQ$2 -> Baldwin | AR11: =$AR$2 -> Baseline
A12: {='AcCountDeer(Trial1)'!A20:AB29} -> 2026 | B12: 10406 | C12: 11810 | D12: 961 | E12: 1193 | F12: 5087 | G12: 5520 | H12: 6569 | I12: 8337 | J12: 49883 | K12: 10167 | L12: 11417 | M12: 4550 | N12: 4847 | O12: 4872 | P12: 6069 | Q12: 13618 | R12: 13618 | S12: 69158 | T12: 9094 | U12: 10025 | V12: 4070 | W12: 4256 | X12: 4358 | Y12: 5693 | Z12: 11394 | AA12: 11394 | AB12: 60284 | AC12: {='AcCountDeer(Trial1)'!B33:J42} -> 10890 | AD12: 2455 | AE12: 3759 | AF12: 570 | AG12: 830 | AH12: 1111 | AI12: 342 | AJ12: 684 | AK12: 1139 | AL12: {='AcCountDeer(Trial1)'!M33:P42} -> 22788 | AM12: 10051 | AN12: 8326 | AO12: 19119 | AP12: {='AcCountDeer(Trial1)'!Z3:Z12} -> NA | AQ12: ='AcCountDeer(Trial1)'!B2 -> Baldwin | AR12: ='AcCountDeer(Trial1)'!B8 -> Increased Harvest
A13: 2027 | B13: 6639 | C13: 6266 | D13: 3500 | E13: 3426 | F13: 3247 | G13: 5351 | H13: 10710 | I13: 10255 | J13: 49394 | K13: 9069 | L13: 8510 | M13: 2904 | N13: 4699 | O13: 7943 | P13: 7466 | Q13: 11314 | R13: 11314 | S13: 63219 | T13: 8112 | U13: 7472 | V13: 2597 | W13: 4126 | X13: 7104 | Y13: 7004 | Z13: 9466 | AA13: 9466 | AB13: 55347 | AC13: 9908 | AD13: 2190 | AE13: 2802 | AF13: 364 | AG13: 805 | AH13: 1812 | AI13: 420 | AJ13: 568 | AK13: 947 | AL13: 18932 | AM13: 14108 | AN13: 6723 | AO13: 15584 | AP13: 0.92 | AQ13: =$AQ$12 -> Baldwin | AR13: =$AR$12 -> Increased Harvest
